Workbook
Name jenjang: REFERENSI!$L$5:$L$11

Sheet MENU
D5: YAYASAN PONDOK PESANTREN
D6: QOMARUL HIDAYAH TRENGGALEK
D7: AKTE NOTARIS: KAYUN WIDIHARSONO,S.H,M.Kn NOMOR: 09 TAHUN 2014
D8: SK MENKUMHAN RI NOMOR: C-598.HT.03.01-2014
D9: ALAMAT : JL. PONOROGO, GONDANG, TUGU,TRENGGALEK KP. 66352 TELP. (0355) 792631

Sheet Form Kepegawaian
B1: DAFTAR ISIAN
A2: BUKU INDUK GURU / KARYAWAN
A3: YAYASAN PONODK PESANTREN QOMARUL HIDAYAH TUGU TRENGGALEK
B5: 1. | C5: N a m a | J5: :
B7: 2. | C7: Gelar | J7: : | K7: Depan | U7: Belakang
B9: 3. | C9: N I P | E9: / | F9: NIGY | J9: :
B11: 4. | C11: Tempat / Tgl. Lahir | J11: : | U11: Tgl. | Y11: Bln. | AC11: Thn.
B13: 5. | C13: Agama | J13: : | K13: I | L13: S | M13: L | N13: A | O13: M
B15: 6. | C15: Alamat | J15: :
Y17: Rt. | AC17: Rw.
B19: 7. | C19: Status rumah | J19: : | K19: Milik sendiri / Kontrak / sewa / numpang / rumah dinas *)
B21: 8. | C21: Status PNS | J21: : | M21: PNS | U21: NON PNS
B23: 9. | C23: Pangkat / Gol (PNS) | J23: : | K23: ………………………………………………………………
B25: 10. | C25: T M T Tendik / KPD | J25: : | K25: Tgl | O25: Bulan | T25: Tahun
K26: Ket. PNS = Tgl. SK Capeg Non PNS = Tgl. Pertama jadi guru
B28: 11. | C28: T M T di Yayasan | J28: : | K28: Tgl | O28: Bulan | T28: Tahun
B30: 12. | C30: T M T di Satker | J30: : | K30: Tgl | O30: Bulan | T30: Tahun
B32: 13. | C32: Sertifikasi | J32: : | L32: Sudah, Tahun | X32: Belum
B34: 14. | C34: NUPTK | J34: :
B36: 15. | C36: NRG | J36: :
B38: 15. | C38: Status Inpassing | J38: : | M38: 1 | N38: Sudah | Q38: 2 | R38: Belum | U38: No SK
K40: Intansi yang menerbitkan
B42: 14. | C42: Pend. Terakhir | J42: : | N42: Jurusan
B44: 15 | C44: Nama Perguruan Tinggi | J44: :
B48: 16. | C48: Mengajar mata pelajaran | J48: :
B50: 17. | C50: Jabatan | J50: : | L50: Kasek | Q50: Wakasek | W50: Guru
B52: 18. | C52: Status Jabatan | J52: : | K52: Tetap / Honorer )*
B54: 19. | C54: Riwayat Pendidikan
B55: No. | C55: Tingkat | H55: Jurusan | R55: Ijazah Tahun | Y55: Tempat
B56: 1.
B57: 2.
B58: 3.
B59: 4.
B60: 5.
B61: 6.
B62: 7.
B64: 20. | C64: Riwayat Pekerjaan
B65: No. | C65: Surat Keputusan | P65: Gaji Pokok | U65: Terhitung | AA65: Masa Kerja
C66: Yayasan/Intansi | H66: Tgl. | L66: Nomor | U66: Mulai | X66: Sampai | AA66: Tahun | AD66: Bulan
B67: 1.
...

Sheet ENTRI
B2: Tanggal entri Data
B3: Tanggal | D3: Bulan | E3: Tahun
B4: 14 | D4: Juli | E4: 2025
A5: NO | B5: SATKER | C5: KODE | D5: DUK | E5: STATUS | F5: KODE | G5: NAMA | H5: NIGY | I5: TEMPAT TANGGAL LAHIR | V5: MASA KERJA | X5: PENDIDIKAN TERAKIR | AA5: INPASSING | AE5: TUGAS UTAMA | AJ5: SERTIFIKASI | AM5: NUPTK
N6: TMT YAYASAN | Q6: TMT SATKER | V6: SELURUHNYA (TAHUN0 | W6: DI SATKER (TAHUN) | BF6: 01 | BG6: - | BK6: Kepala Sekolah | BL6: 18
I7: TEMPAT | J7: TANGGAL | K7: BULAN | L7: TAHUN | N7: Tanggal | O7: Bulan | P7: Tahun | Q7: Tanggal | R7: Bulan | S7: Tahun | T7: Tahun | U7: Tahun | X7: JENJANG | Y7: JURUSAN | Z7: TAHUN LULUS | AA7: STATUS | AB7: JABATAN | AC7: PANGKAT | AD7: GOLONGAN | AE7: MENGAJAR | AF7: JTM | AG7: TUGAS TAMBAHAN | AH7: EKUIVALEN | AI7: JML BEBAN KERJA | AJ7: STATUS | AK7: TAHUN LULUS | AL7: NRG | BF7: 02 | BG7: 1940 | BK7: Kepala Madrasah | BL7: 18
A8: 1 | B8: RA | C8: =IFERROR(VLOOKUP(B8,REFERENSI!$C$6:$D$15,2,FALSE)," ") -> 02 | E8: Guru | F8: =IFERROR(VLOOKUP(E8,REFERENSI!$F$5:$G$6,2,FALSE)," ") -> 01 | G8: Hj.AZ.MUTIATUN,A.Ma | H8: =IFERROR((M8&" "&P8&O8&" "&C8&" "&F8&" "&D8)," ") -> 19410413 200107 02 01 | I8: Trenggalek | J8: 13 | K8: 04 | L8: 1941 | M8: =L8&K8&J8 -> 19410413 | N8: 01 | O8: 07 | P8: 2001 | Q8: 01 | R8: 07 | S8: 2001 | T8: =IFERROR(($E$4-S8)," ") -> 24 | U8: =$E$4-P8 -> 24 | V8: =IF(U8=$E$4," ",U8) -> 24 | W8: =IF(T8=$E$4," ",T8) -> 24 | X8: D II | Y8: PAI | Z8: 1995 | AA8: BELUM | AC8: =IFERROR(VLOOKUP(AD8,REFERENSI!$H$5:$I$13,2,FALSE)," ") | AE8: Guru Kelas | AF8: 0 | AG8: Kepala Sekolah | AH8: =VLOOKUP(AG8,$BK$6:$BL$19,2,FALSE) -> 18 | AI8: =IFERROR((AF8+AH8)," ") -> 18 | AJ8: BELUM | AM8: - | BF8: 03 | BG8: 1941 | BK8: Waka Kurikulum | BL8: 12
A9: 2 | B9: RA | C9: =IFERROR(VLOOKUP(B9,REFERENSI!$C$6:$D$15,2,FALSE)," ") -> 02 | E9: Guru | F9: =IFERROR(VLOOKUP(E9,REFERENSI!$F$5:$G$6,2,FALSE)," ") -> 01 | G9: RINA WIJAYANTI,S.Pd.I | H9: =IFERROR((M9&" "&P9&O9&" "&C9&" "&F9&" "&D9)," ") -> 19850425 200307 02 01 | I9: Trenggalek | J9: 25 | K9: 04 | L9: 1985 | M9: =L9&K9&J9 -> 19850425 | N9: 01 | O9: 07 | P9: 2003 | Q9: 01 | R9: 07 | S9: 2003 | T9: =IFERROR(($E$4-S9)," ") -> 22 | U9: =$E$4-P9 -> 22 | V9: =IF(U9=$E$4," ",U9) -> 22 | W9: =IF(T9=$E$4," ",T9) -> 22 | X9: S1 | Y9: PAI | Z9: 2008 | AA9: SUDAH | AB9: GURU PERTAMA | AC9: =IFERROR(VLOOKUP(AD9,REFERENSI!$H$5:$I$13,2,FALSE)," ") -> PENATA MUDA | AD9: III A | AE9: Guru Kelas | AF9: 30 | AG9: - | AH9: =VLOOKUP(AG9,$BK$6:$BL$19,2,FALSE) -> - | AI9: =IFERROR((AF9+AH9)," ") | AJ9: SUDAH | AK9: 2014 | AM9: 4757763664300032 | BF9: 04 | BG9: 1942 | BK9: Waka Kesiswaan | BL9: 12
A10: 3 | B10: RA | C10: =IFERROR(VLOOKUP(B10,REFERENSI!$C$6:$D$15,2,FALSE)," ") -> 02 | E10: Guru | F10: =IFERROR(VLOOKUP(E10,REFERENSI!$F$5:$G$6,2,FALSE)," ") -> 01 | G10: HIDAYATUL LAILI,S.Ag | H10: =IFERROR((M10&" "&P10&O10&" "&C10&" "&F10&" "&D10)," ") -> 19731025 200501 02 01 | I10: Trenggalek | J10: 25 | K10: 10 | L10: 1973 | M10: =L10&K10&J10 -> 19731025 | N10: 02 | O10: 01 | P10: 2005 | Q10: 02 | R10: 01 | S10: 2005 | T10: =$E$4-S10 -> 20 | U10: =$E$4-P10 -> 20 | V10: =IF(U10=$E$4," ",U10) -> 20 | W10: =IF(T10=$E$4," ",T10) -> 20 | X10: S1 | Y10: PAI | Z10: 1995 | AA10: SUDAH | AB10: GURU MADYA | AC10: =IFERROR(VLOOKUP(AD10,REFERENSI!$H$5:$I$13,2,FALSE)," ") -> PENATA MUDA TK. I | AD10: III B | AE10: Guru Kelas | AF10: 30 | AG10: - | AH10: =VLOOKUP(AG10,$BK$6:$BL$19,2,FALSE) -> - | AI10: =IFERROR((AF10+AH10)," ") | AJ10: SUDAH | AK10: 2012 | AL10: 120212191003 | AM10: 1357751652300013 | BF10: 05 | BG10: 1943 | BK10: Waka Sarana Prasarana | BL10: 12
A11: 4 | B11: RA | C11: =IFERROR(VLOOKUP(B11,REFERENSI!$C$6:$D$15,2,FALSE)," ") -> 02 | E11: Guru | F11: =IFERROR(VLOOKUP(E11,REFERENSI!$F$5:$G$6,2,FALSE)," ") -> 01 | G11: RENI FARICHA ARIANI,S.Pd.I | H11: =IFERROR((M11&" "&P11&O11&" "&C11&" "&F11&" "&D11)," ") -> 19850116 200607 02 01 | I11: Trenggalek | J11: 16 | K11: 01 | L11: 1985 | M11: =L11&K11&J11 -> 19850116 | N11: 01 | O11: 07 | P11: 2006 | Q11: 01 | R11: 07 | S11: 2006 | T11: =$E$4-S11 -> 19 | U11: =$E$4-P11 -> 19 | V11: =IF(U11=$E$4," ",U11) -> 19 | W11: =IF(T11=$E$4," ",T11) -> 19 | X11: S1 | Y11: PGMI | Z11: 2012 | AA11: BELUM | AC11: =IFERROR(VLOOKUP(AD11,REFERENSI!$H$5:$I$13,2,FALSE)," ") | AE11: Guru Kelas | AF11: 30 | AG11: - | AH11: =VLOOKUP(AG11,$BK$6:$BL$19,2,FALSE) -> - | AI11: =IFERROR((AF11+AH11)," ") | AJ11: BELUM | AM11: 3448763664300032 | BF11: 06 | BG11: 1944 | BK11: Waka Humas | BL11: 12
A12: 5 | B12: PAUD | C12: =IFERROR(VLOOKUP(B12,REFERENSI!$C$6:$D$15,2,FALSE)," ") -> 01 | E12: Guru | F12: =IFERROR(VLOOKUP(E12,REFERENSI!$F$5:$G$6,2,FALSE)," ") -> 01 | G12: ISTIQOMAH | H12: =IFERROR((M12&" "&P12&O12&" "&C12&" "&F12&" "&D12)," ") -> 19830614 200707 01 01 | I12: Trenggalek | J12: 14 | K12: 06 | L12: 1983 | M12: =L12&K12&J12 -> 19830614 | N12: 16 | O12: 07 | P12: 2007 | Q12: 16 | R12: 07 | S12: 2007 | T12: =$E$4-S12 -> 18 | U12: =$E$4-P12 -> 18 | V12: =IF(U12=$E$4," ",U12) -> 18 | W12: =IF(T12=$E$4," ",T12) -> 18 | X12: S1 | Y12: PAUD | Z12: 2002 | AA12: BELUM | AB12: GURU PERTAMA | AC12: =IFERROR(VLOOKUP(AD12,REFERENSI!$H$5:$I$13,2,FALSE)," ") | AE12: Guru sentra | AF12: 26 | AG12: - | AH12: =VLOOKUP(AG12,$BK$6:$BL$19,2,FALSE) -> - | AI12: =IFERROR((AF12+AH12)," ") | AJ12: SUDAH | AK12: 2010 | AL12: 021389407006 | AM12: 1641746650300012 | BF12: 07 | BG12: 1945 | BK12: Kepala Lab. IPA | BL12: 12
A13: 6 | B13: PAUD | C13: =IFERROR(VLOOKUP(B13,REFERENSI!$C$6:$D$15,2,FALSE)," ") -> 01 | E13: Guru | F13: =IFERROR(VLOOKUP(E13,REFERENSI!$F$5:$G$6,2,FALSE)," ") -> 01 | G13: IKA SULISTIOWATI | H13: =IFERROR((M13&" "&P13&O13&" "&C13&" "&F13&" "&D13)," ") -> 19851023 200807 01 01 | I13: Trenggalek | J13: 23 | K13: 10 | L13: 1985 | M13: =L13&K13&J13 -> 19851023 | N13: 14 | O13: 07 | P13: 2008 | Q13: 14 | R13: 07 | S13: 2008 | T13: =$E$4-S13 -> 17 | U13: =$E$4-P13 -> 17 | V13: =IF(U13=$E$4," ",U13) -> 17 | W13: =IF(T13=$E$4," ",T13) -> 17 | X13: S1 | Y13: B.INGGRIS | Z13: 2010 | AA13: BELUM | AB13: GURU PERTAMA | AC13: =IFERROR(VLOOKUP(AD13,REFERENSI!$H$5:$I$13,2,FALSE)," ") | AE13: Guru sentra | AF13: 25 | AG13: - | AH13: =VLOOKUP(AG13,$BK$6:$BL$19,2,FALSE) -> - | AI13: =IFERROR((AF13+AH13)," ") | AJ13: SUDAH | AK13: 2009 | AL13: 091535962003 | AM13: 4538757658300060 | BF13: 08 | BG13: 1946 | BK13: Kepala Lab. Bahasa | BL13: 12
A14: 7 | B14: PAUD | C14: =IFERROR(VLOOKUP(B14,REFERENSI!$C$6:$D$15,2,FALSE)," ") -> 01 | E14: Tenaga Kependidikan | F14: =IFERROR(VLOOKUP(E14,REFERENSI!$F$5:$G$6,2,FALSE)," ") -> 02 | G14: SITI MAESAROH | H14: =IFERROR((M14&" "&P14&O14&" "&C14&" "&F14&" "&D14)," ") -> 19840707 201307 01 02 | I14: Trenggalek | J14: 07 | K14: 07 | L14: 1984 | M14: =L14&K14&J14 -> 19840707 | N14: 08 | O14: 07 | P14: 2013 | Q14: 08 | R14: 07 | S14: 2013 | T14: =$E$4-S14 -> 12 | U14: =$E$4-P14 -> 12 | V14: =IF(U14=$E$4," ",U14) -> 12 | W14: =IF(T14=$E$4," ",T14) -> 12 | X14: SLTA | Y14: SK | Z14: 2003 | AA14: BELUM | AB14: GURU PERTAMA | AC14: =IFERROR(VLOOKUP(AD14,REFERENSI!$H$5:$I$13,2,FALSE)," ") | AE14: Guru sentra | AF14: 25 | AG14: - | AH14: =VLOOKUP(AG14,$BK$6:$BL$19,2,FALSE) -> - | AI14: =IFERROR((AF14+AH14)," ") | AJ14: SUDAH | AK14: 2012 | AL14: 122172183005 | AM14: 4433758659300190 | BF14: 09 | BG14: 1947 | BK14: Kepala Lab. Komputer | BL14: 12
A15: 8 | B15: MI | C15: =IFERROR(VLOOKUP(B15,REFERENSI!$C$6:$D$15,2,FALSE)," ") -> 03 | D15: 67 | E15: Guru | F15: =IFERROR(VLOOKUP(E15,REFERENSI!$F$5:$G$6,2,FALSE)," ") -> 01 | G15: SITI CHOIRIYAH,S.Pd.I | H15: =IFERROR((M15&" "&P15&O15&" "&C15&" "&F15&" "&D15)," ") -> 19680903 199507 03 01 67 | I15: Trenggalek | J15: 03 | K15: 09 | L15: 1968 | M15: =L15&K15&J15 -> 19680903 | N15: 05 | O15: 07 | P15: 1995 | Q15: 05 | R15: 07 | S15: 1995 | T15: =$E$4-S15 -> 30 | U15: =$E$4-P15 -> 30 | V15: =IF(U15=$E$4," ",U15) -> 30 | W15: =IF(T15=$E$4," ",T15) -> 30 | X15: S1 | Y15: PAI | Z15: 2009 | AA15: SUDAH | AB15: GURU DEWASA | AC15: =IFERROR(VLOOKUP(AD15,REFERENSI!$H$5:$I$13,2,FALSE)," ") -> PENATA | AD15: III C | AE15: Guru Kelas | AF15: 26 | AG15: - | AH15: =VLOOKUP(AG15,$BK$6:$BL$19,2,FALSE) -> - | AI15: =IFERROR((AF15+AH15)," ") | AJ15: BELUM | AM15: 6858764666200002 | BF15: 10 | BG15: 1948 | BK15: Kepala Lab. Produksi | BL15: 12
A16: 9 | B16: MI | C16: =IFERROR(VLOOKUP(B16,REFERENSI!$C$6:$D$15,2,FALSE)," ") -> 03 | D16: 01 | E16: Guru | F16: =IFERROR(VLOOKUP(E16,REFERENSI!$F$5:$G$6,2,FALSE)," ") -> 01 | G16: IMMAROTUS SA'ADAH,S.Pd.I | H16: =IFERROR((M16&" "&P16&O16&" "&C16&" "&F16&" "&D16)," ") -> 19790602 200007 03 01 01 | I16: Trenggalek | J16: 02 | K16: 06 | L16: 1979 | M16: =L16&K16&J16 -> 19790602 | N16: 01 | O16: 07 | P16: 2000 | Q16: 01 | R16: 07 | S16: 2000 | T16: =$E$4-S16 -> 25 | U16: =$E$4-P16 -> 25 | V16: =IF(U16=$E$4," ",U16) -> 25 | W16: =IF(T16=$E$4," ",T16) -> 25 | X16: S1 | Y16: PAI | Z16: 2004 | AA16: SUDAH | AB16: GURU PERTAMA | AC16: =IFERROR(VLOOKUP(AD16,REFERENSI!$H$5:$I$13,2,FALSE)," ") -> PENATA MUDA TK. I | AD16: III B | AE16: Guru Kelas | AF16: 25 | AG16: - | AH16: =VLOOKUP(AG16,$BK$6:$BL$19,2,FALSE) -> - | AI16: =IFERROR((AF16+AH16)," ") | AJ16: BELUM | AM16: 4444766668110012 | BF16: 11 | BG16: 1949 | BK16: Kepala Perpustakaan | BL16: 12
A17: 10 | B17: MI | C17: =IFERROR(VLOOKUP(B17,REFERENSI!$C$6:$D$15,2,FALSE)," ") -> 03 | D17: 11 | E17: Guru | F17: =IFERROR(VLOOKUP(E17,REFERENSI!$F$5:$G$6,2,FALSE)," ") -> 01 | G17: NAILI ROHMAH,S.E | H17: =IFERROR((M17&" "&P17&O17&" "&C17&" "&F17&" "&D17)," ") -> 19800101 200507 03 01 11 | I17: Trenggalek | J17: 01 | K17: 01 | L17: 1980 | M17: =L17&K17&J17 -> 19800101 | N17: 11 | O17: 07 | P17: 2005 | Q17: 11 | R17: 07 | S17: 2005 | T17: =$E$4-S17 -> 20 | U17: =$E$4-P17 -> 20 | V17: =IF(U17=$E$4," ",U17) -> 20 | W17: =IF(T17=$E$4," ",T17) -> 20 | X17: S1 | Y17: AKUNTASI | Z17: 2003 | AA17: SUDAH | AB17: GURU MADYA | AC17: =IFERROR(VLOOKUP(AD17,REFERENSI!$H$5:$I$13,2,FALSE)," ") -> PENATA MUDA TK. I | AD17: III B | AE17: Guru Kelas | AF17: 26 | AG17: - | AH17: =VLOOKUP(AG17,$BK$6:$BL$19,2,FALSE) -> - | AI17: =IFERROR((AF17+AH17)," ") | AJ17: BELUM | AM17: 20541857191001 | BF17: 12 | BG17: 1950 | BK17: Kepala Bengkel | BL17: 12
A18: 11 | B18: MI | C18: =IFERROR(VLOOKUP(B18,REFERENSI!$C$6:$D$15,2,FALSE)," ") -> 03 | D18: 24 | E18: Guru | F18: =IFERROR(VLOOKUP(E18,REFERENSI!$F$5:$G$6,2,FALSE)," ") -> 01 | G18: DUKAN KHOIRI,S.Pd.I | H18: =IFERROR((M18&" "&P18&O18&" "&C18&" "&F18&" "&D18)," ") -> 19860526 200509 03 01 24 | I18: Trenggalek | J18: 26 | K18: 05 | L18: 1986 | M18: =L18&K18&J18 -> 19860526 | N18: 01 | O18: 09 | P18: 2005 | Q18: 01 | R18: 09 | S18: 2005 | T18: =$E$4-S18 -> 20 | U18: =$E$4-P18 -> 20 | V18: =IF(U18=$E$4," ",U18) -> 20 | W18: =IF(T18=$E$4," ",T18) -> 20 | X18: S1 | Y18: PAI | Z18: 2010 | AA18: BELUM | AC18: =IFERROR(VLOOKUP(AD18,REFERENSI!$H$5:$I$13,2,FALSE)," ") | AE18: GURU KELAS AGAMA | AF18: 26 | AG18: - | AH18: =VLOOKUP(AG18,$BK$6:$BL$19,2,FALSE) -> - | AI18: =IFERROR((AF18+AH18)," ") | AJ18: BELUM | AM18: 20541857189001 | BF18: 13 | BG18: 1951 | BK18: Kepala Tata Usaha | BL18: -
A19: 12 | B19: MTs | C19: =IFERROR(VLOOKUP(B19,REFERENSI!$C$6:$D$15,2,FALSE)," ") -> 04 | D19: 01 | E19: Guru | F19: =IFERROR(VLOOKUP(E19,REFERENSI!$F$5:$G$6,2,FALSE)," ") -> 01 | G19: RION ADI WIJAYA,S.Pd | H19: =IFERROR((M19&" "&P19&O19&" "&C19&" "&F19&" "&D19)," ") -> 19880112 200807 04 01 01 | I19: Trenggalek | J19: 12 | K19: 01 | L19: 1988 | M19: =L19&K19&J19 -> 19880112 | N19: 01 | O19: 07 | P19: 2008 | Q19: 01 | R19: 07 | S19: 2020 | T19: =$E$4-S19 -> 5 | U19: =$E$4-P19 -> 17 | V19: =IF(U19=$E$4," ",U19) -> 17 | W19: =IF(T19=$E$4," ",T19) -> 5 | X19: S1 | Y19: PBS/PBSI | Z19: 2013 | AA19: BELUM | AC19: =IFERROR(VLOOKUP(AD19,REFERENSI!$H$5:$I$13,2,FALSE)," ") | AE19: GURU PENJASKES | AF19: 24 | AG19: - | AH19: =VLOOKUP(AG19,$BK$6:$BL$19,2,FALSE) -> - | AI19: =IFERROR((AF19+AH19)," ") | AM19: 20541857187001 | BF19: 14 | BG19: 1952 | BK19: - | BL19: -
A20: 14 | B20: MI | C20: =IFERROR(VLOOKUP(B20,REFERENSI!$C$6:$D$15,2,FALSE)," ") -> 03 | D20: 01 | E20: Guru | F20: =IFERROR(VLOOKUP(E20,REFERENSI!$F$5:$G$6,2,FALSE)," ") -> 01 | G20: SITI SHOLIKAH,S.Pd | H20: =IFERROR((M20&" "&P20&O20&" "&C20&" "&F20&" "&D20)," ") -> 19890205 201110 03 01 01 | I20: Trenggalek | J20: 05 | K20: 02 | L20: 1989 | M20: =L20&K20&J20 -> 19890205 | N20: 01 | O20: 10 | P20: 2011 | Q20: 01 | R20: 10 | S20: 2011 | T20: =$E$4-S20 -> 14 | U20: =$E$4-P20 -> 14 | V20: =IF(U20=$E$4," ",U20) -> 14 | W20: =IF(T20=$E$4," ",T20) -> 14 | X20: S1 | Y20: PBS/PBSI | Z20: 2012 | AA20: BELUM | AC20: =IFERROR(VLOOKUP(AD20,REFERENSI!$H$5:$I$13,2,FALSE)," ") | AG20: - | AH20: =VLOOKUP(AG20,$BK$6:$BL$19,2,FALSE) -> - | AI20: =IFERROR((AF20+AH20)," ") | AJ20: BELUM | AM20: 6363763665120003 | BF20: 15 | BG20: 1954
A21: 17 | B21: MI | C21: =IFERROR(VLOOKUP(B21,REFERENSI!$C$6:$D$15,2,FALSE)," ") -> 03 | D21: 01 | E21: Guru | F21: =IFERROR(VLOOKUP(E21,REFERENSI!$F$5:$G$6,2,FALSE)," ") -> 01 | G21: MUSTANGIN,S.Pd.I | H21: =IFERROR((M21&" "&P21&O21&" "&C21&" "&F21&" "&D21)," ") -> 19851031 201001 03 01 01 | I21: Trenggalek | J21: 31 | K21: 10 | L21: 1985 | M21: =L21&K21&J21 -> 19851031 | N21: 01 | O21: 01 | P21: 2010 | Q21: 01 | R21: 01 | S21: 2010 | T21: =$E$4-S21 -> 15 | U21: =$E$4-P21 -> 15 | V21: =IF(U21=$E$4," ",U21) -> 15 | W21: =IF(T21=$E$4," ",T21) -> 15 | X21: S1 | Y21: PAI | Z21: 2012 | AA21: BELUM | AC21: =IFERROR(VLOOKUP(AD21,REFERENSI!$H$5:$I$13,2,FALSE)," ") | AE21: GURU AGAMA | AF21: 24 | AG21: - | AH21: =VLOOKUP(AG21,$BK$6:$BL$19,2,FALSE) -> - | AI21: =IFERROR((AF21+AH21)," ") | AJ21: SUDAH | AK21: 2009 | AL21: 091535962003 | AM21: 4538757658300062 | BF21: 16 | BG21: 1957
A22: 19 | B22: MI | C22: =IFERROR(VLOOKUP(B22,REFERENSI!$C$6:$D$15,2,FALSE)," ") -> 03 | D22: 81 | E22: Guru | F22: =IFERROR(VLOOKUP(E22,REFERENSI!$F$5:$G$6,2,FALSE)," ") -> 01 | G22: ENDANG SUMARSIH,S.Pd.I | H22: =IFERROR((M22&" "&P22&O22&" "&C22&" "&F22&" "&D22)," ") -> 19800506 200407 03 01 81 | I22: Tulung agung | J22: 06 | K22: 05 | L22: 1980 | M22: =L22&K22&J22 -> 19800506 | N22: 18 | O22: 07 | P22: 2004 | Q22: 18 | R22: 07 | S22: 2004 | T22: =$E$4-S22 -> 21 | U22: =$E$4-P22 -> 21 | V22: =IF(U22=$E$4," ",U22) -> 21 | W22: =IF(T22=$E$4," ",T22) -> 21 | X22: S1 | Y22: PAI | Z22: 2004 | AA22: BELUM | AC22: =IFERROR(VLOOKUP(AD22,REFERENSI!$H$5:$I$13,2,FALSE)," ") | AF22: 25 | AG22: - | AH22: =VLOOKUP(AG22,$BK$6:$BL$19,2,FALSE) -> - | AI22: =IFERROR((AF22+AH22)," ") | AJ22: SUDAH | AK22: 2009 | AL22: 095021192809 | AM22: 4435751652200022 | BF22: 17 | BG22: 1959
A23: 20 | B23: MI | C23: =IFERROR(VLOOKUP(B23,REFERENSI!$C$6:$D$15,2,FALSE)," ") -> 03 | D23: 01 | E23: Guru | F23: =IFERROR(VLOOKUP(E23,REFERENSI!$F$5:$G$6,2,FALSE)," ") -> 01 | G23: NUZULUL MUKAROMAH,S.Pd.I | H23: =IFERROR((M23&" "&P23&O23&" "&C23&" "&F23&" "&D23)," ") -> 19861005 200509 03 01 01 | I23: Trenggalek | J23: 05 | K23: 10 | L23: 1986 | M23: =L23&K23&J23 -> 19861005 | N23: 01 | O23: 09 | P23: 2005 | Q23: 01 | R23: 09 | S23: 2005 | T23: =$E$4-S23 -> 20 | U23: =$E$4-P23 -> 20 | V23: =IF(U23=$E$4," ",U23) -> 20 | W23: =IF(T23=$E$4," ",T23) -> 20 | X23: S1 | Y23: PAI | Z23: 2005 | AA23: BELUM | AC23: =IFERROR(VLOOKUP(AD23,REFERENSI!$H$5:$I$13,2,FALSE)," ") | AG23: - | AH23: =VLOOKUP(AG23,$BK$6:$BL$19,2,FALSE) -> - | AI23: =IFERROR((AF23+AH23)," ") | BF23: 18 | BG23: 1961
A24: 21 | B24: MI | C24: =IFERROR(VLOOKUP(B24,REFERENSI!$C$6:$D$15,2,FALSE)," ") -> 03 | D24: 66 | E24: Guru | F24: =IFERROR(VLOOKUP(E24,REFERENSI!$F$5:$G$6,2,FALSE)," ") -> 01 | G24: KHOIRUL BAHRI,S.Pd | H24: =IFERROR((M24&" "&P24&O24&" "&C24&" "&F24&" "&D24)," ") -> 19730301 200007 03 01 66 | I24: Trenggalek | J24: 01 | K24: 03 | L24: 1973 | M24: =L24&K24&J24 -> 19730301 | N24: 01 | O24: 07 | P24: 2000 | Q24: 01 | R24: 07 | S24: 2000 | T24: =$E$4-S24 -> 25 | U24: =$E$4-P24 -> 25 | V24: =IF(U24=$E$4," ",U24) -> 25 | W24: =IF(T24=$E$4," ",T24) -> 25 | X24: S1 | Y24: PIPS/PKN | AA24: SUDAH | AC24: =IFERROR(VLOOKUP(AD24,REFERENSI!$H$5:$I$13,2,FALSE)," ") | AF24: 26 | AG24: - | AH24: =VLOOKUP(AG24,$BK$6:$BL$19,2,FALSE) -> - | AI24: =IFERROR((AF24+AH24)," ") | BF24: 19 | BG24: 1962
A25: 22 | B25: MTs | C25: =IFERROR(VLOOKUP(B25,REFERENSI!$C$6:$D$15,2,FALSE)," ") -> 04 | D25: 57 | E25: Kepala Madrasah | F25: =IFERROR(VLOOKUP(E25,REFERENSI!$F$5:$G$6,2,FALSE)," ") | G25: H. SYAIFUL MAHBUB, S.Sy | H25: =IFERROR((M25&" "&P25&O25&" "&C25&" "&F25&" "&D25)," ") -> 19860214 201407 04 57 | I25: Trenggalek | J25: 14 | K25: 02 | L25: 1986 | M25: =L25&K25&J25 -> 19860214 | N25: 16 | O25: 07 | P25: 2014 | Q25: 16 | R25: 07 | S25: 2014 | T25: =$E$4-S25 -> 11 | U25: =$E$4-P25 -> 11 | V25: =IF(U25=$E$4," ",U25) -> 11 | W25: =IF(T25=$E$4," ",T25) -> 11 | X25: S1 | Y25: Syariah | Z25: 2013 | AA25: BELUM | AC25: =IFERROR(VLOOKUP(AD25,REFERENSI!$H$5:$I$13,2,FALSE)," ") | AE25: Aswaja | AG25: Kepala Madrasah | AH25: =VLOOKUP(AG25,$BK$6:$BL$19,2,FALSE) -> 18 | AI25: =IFERROR((AF25+AH25)," ") -> 18 | AJ25: BELUM | AM25: 20542411186001 | BF25: 20 | BG25: 1963
A26: 23 | B26: MTs | C26: =IFERROR(VLOOKUP(B26,REFERENSI!$C$6:$D$15,2,FALSE)," ") -> 04 | D26: 26 | E26: Guru | F26: =IFERROR(VLOOKUP(E26,REFERENSI!$F$5:$G$6,2,FALSE)," ") -> 01 | G26: INDRA GUNAWAN,S.Pd.I | H26: =IFERROR((M26&" "&P26&O26&" "&C26&" "&F26&" "&D26)," ") -> 19891129 201007 04 01 26 | I26: Trenggalek | J26: 29 | K26: 11 | L26: 1989 | M26: =L26&K26&J26 -> 19891129 | N26: 12 | O26: 07 | P26: 2010 | Q26: 12 | R26: 07 | S26: 2010 | T26: =$E$4-S26 -> 15 | U26: =$E$4-P26 -> 15 | V26: =IF(U26=$E$4," ",U26) -> 15 | W26: =IF(T26=$E$4," ",T26) -> 15 | X26: S1 | Y26: Pendidikan Agama Islam | Z26: 2015 | AA26: BELUM | AC26: =IFERROR(VLOOKUP(AD26,REFERENSI!$H$5:$I$13,2,FALSE)," ") | AE26: Aswaja | AF26: 7 | AG26: Kepala Tata Usaha | AH26: =VLOOKUP(AG26,$BK$6:$BL$19,2,FALSE) -> - | AI26: =IFERROR((AF26+AH26)," ") | AJ26: BELUM | AK26: - | AL26: - | AM26: 20542411189001 | BF26: 21 | BG26: 1964
A27: 24 | B27: MTs | C27: =IFERROR(VLOOKUP(B27,REFERENSI!$C$6:$D$15,2,FALSE)," ") -> 04 | D27: 95 | E27: Guru | F27: =IFERROR(VLOOKUP(E27,REFERENSI!$F$5:$G$6,2,FALSE)," ") -> 01 | G27: SUGENG SUPRAYOGO, S.Pd | H27: =IFERROR((M27&" "&P27&O27&" "&C27&" "&F27&" "&D27)," ") -> 19830428 200507 04 01 95 | I27: Trenggalek | J27: 28 | K27: 04 | L27: 1983 | M27: =L27&K27&J27 -> 19830428 | N27: 18 | O27: 07 | P27: 2005 | Q27: 18 | R27: 07 | S27: 2005 | T27: =$E$4-S27 -> 20 | U27: =$E$4-P27 -> 20 | V27: =IF(U27=$E$4," ",U27) -> 20 | W27: =IF(T27=$E$4," ",T27) -> 20 | X27: S1 | Y27: Pendidikan Agama Islam | Z27: 2016 | AA27: BELUM | AC27: =IFERROR(VLOOKUP(AD27,REFERENSI!$H$5:$I$13,2,FALSE)," ") | AE27: Seni Budaya | AG27: Waka Kurikulum | AH27: =VLOOKUP(AG27,$BK$6:$BL$19,2,FALSE) -> 12 | AI27: =IFERROR((AF27+AH27)," ") -> 12 | AJ27: SUDAH | AK27: 2014 | AM27: 3760761663110042 | BF27: 22 | BG27: 1965
A28: 25 | B28: MTs | C28: =IFERROR(VLOOKUP(B28,REFERENSI!$C$6:$D$15,2,FALSE)," ") -> 04 | D28: 95 | E28: Guru | F28: =IFERROR(VLOOKUP(E28,REFERENSI!$F$5:$G$6,2,FALSE)," ") -> 01 | G28: BAROKALLAH, S.Sos | H28: =IFERROR((M28&" "&P28&O28&" "&C28&" "&F28&" "&D28)," ") -> 19771010 200507 04 01 95 | I28: Kediri | J28: 10 | K28: 10 | L28: 1977 | M28: =L28&K28&J28 -> 19771010 | N28: 16 | O28: 07 | P28: 2005 | Q28: 16 | R28: 07 | S28: 2005 | T28: =$E$4-S28 -> 20 | U28: =$E$4-P28 -> 20 | V28: =IF(U28=$E$4," ",U28) -> 20 | W28: =IF(T28=$E$4," ",T28) -> 20 | X28: S1 | Y28: Ilmu Sosial dan Ilmu Politik | Z28: 2005 | AA28: BELUM | AC28: =IFERROR(VLOOKUP(AD28,REFERENSI!$H$5:$I$13,2,FALSE)," ") | AE28: PKn | AG28: Waka Sarana Prasarana | AH28: =VLOOKUP(AG28,$BK$6:$BL$19,2,FALSE) -> 12 | AI28: =IFERROR((AF28+AH28)," ") -> 12 | AJ28: SUDAH | AK28: 2013 | AL28: 131542179003 | AM28: 7342755657110113 | BF28: 23 | BG28: 1966
A29: 26 | B29: MTs | C29: =IFERROR(VLOOKUP(B29,REFERENSI!$C$6:$D$15,2,FALSE)," ") -> 04 | D29: 62 | E29: Guru | F29: =IFERROR(VLOOKUP(E29,REFERENSI!$F$5:$G$6,2,FALSE)," ") -> 01 | G29: SITI MUSAROPAH, S.Ag | H29: =IFERROR((M29&" "&P29&O29&" "&C29&" "&F29&" "&D29)," ") -> 19700709 199307 04 01 62 | I29: Trenggalek | J29: 09 | K29: 07 | L29: 1970 | M29: =L29&K29&J29 -> 19700709 | N29: 16 | O29: 07 | P29: 1993 | Q29: 16 | R29: 07 | S29: 1993 | T29: =$E$4-S29 -> 32 | U29: =$E$4-P29 -> 32 | V29: =IF(U29=$E$4," ",U29) -> 32 | W29: =IF(T29=$E$4," ",T29) -> 32 | X29: S1 | Y29: Pendidikan Agama Islam | Z29: 1993 | AA29: SUDAH | AC29: =IFERROR(VLOOKUP(AD29,REFERENSI!$H$5:$I$13,2,FALSE)," ") | AE29: Aqidah | AG29: Waka Humas | AH29: =VLOOKUP(AG29,$BK$6:$BL$19,2,FALSE) -> 12 | AI29: =IFERROR((AF29+AH29)," ") -> 12 | AJ29: SUDAH | AK29: 2009 | AL29: 091688417014 | AM29: 8041748650300023 | BF29: 24 | BG29: 1967
A30: 27 | B30: MTs | C30: =IFERROR(VLOOKUP(B30,REFERENSI!$C$6:$D$15,2,FALSE)," ") -> 04 | D30: 65 | E30: Guru | F30: =IFERROR(VLOOKUP(E30,REFERENSI!$F$5:$G$6,2,FALSE)," ") -> 01 | G30: SUDARTI, S.Ag | H30: =IFERROR((M30&" "&P30&O30&" "&C30&" "&F30&" "&D30)," ") -> 19651119 199407 04 01 65 | I30: Trenggalek | J30: 19 | K30: 11 | L30: 1965 | M30: =L30&K30&J30 -> 19651119 | N30: 18 | O30: 07 | P30: 1994 | Q30: 18 | R30: 07 | S30: 1994 | T30: =$E$4-S30 -> 31 | U30: =$E$4-P30 -> 31 | V30: =IF(U30=$E$4," ",U30) -> 31 | W30: =IF(T30=$E$4," ",T30) -> 31 | X30: S1 | Y30: Pendidikan Agama Islam | Z30: 1992 | AA30: SUDAH | AC30: =IFERROR(VLOOKUP(AD30,REFERENSI!$H$5:$I$13,2,FALSE)," ") | AE30: SKI, Qur'an Hadist | AG30: - | AH30: =VLOOKUP(AG30,$BK$6:$BL$19,2,FALSE) -> - | AI30: =IFERROR((AF30+AH30)," ") | AJ30: SUDAH | AK30: 2009 | AL30: 092190392017 | AM30: 5451743647380003 | BF30: 25 | BG30: 1968
A31: 28 | B31: MTs | C31: =IFERROR(VLOOKUP(B31,REFERENSI!$C$6:$D$15,2,FALSE)," ") -> 04 | D31: 70 | E31: Guru | F31: =IFERROR(VLOOKUP(E31,REFERENSI!$F$5:$G$6,2,FALSE)," ") -> 01 | G31: ANIF KUSNAWATI, S.Ag | H31: =IFERROR((M31&" "&P31&O31&" "&C31&" "&F31&" "&D31)," ") -> 19750630 199607 04 01 70 | I31: Trenggalek | J31: 30 | K31: 06 | L31: 1975 | M31: =L31&K31&J31 -> 19750630 | N31: 17 | O31: 07 | P31: 1996 | Q31: 17 | R31: 07 | S31: 1996 | T31: =$E$4-S31 -> 29 | U31: =$E$4-P31 -> 29 | V31: =IF(U31=$E$4," ",U31) -> 29 | W31: =IF(T31=$E$4," ",T31) -> 29 | X31: S1 | Y31: Pendidikan Agama Islam | Z31: 1997 | AA31: SUDAH | AC31: =IFERROR(VLOOKUP(AD31,REFERENSI!$H$5:$I$13,2,FALSE)," ") | AE31: IPS | AG31: - | AH31: =VLOOKUP(AG31,$BK$6:$BL$19,2,FALSE) -> - | AI31: =IFERROR((AF31+AH31)," ") | AJ31: SUDAH | AK31: 2009 | AL31: 092737942012 | AM31: 6962753654300002 | BF31: 26 | BG31: 1969
A32: 29 | B32: MTs | C32: =IFERROR(VLOOKUP(B32,REFERENSI!$C$6:$D$15,2,FALSE)," ") -> 04 | D32: 70 | E32: Guru | F32: =IFERROR(VLOOKUP(E32,REFERENSI!$F$5:$G$6,2,FALSE)," ") -> 01 | G32: IMAM MAKRUS, S.Ag | H32: =IFERROR((M32&" "&P32&O32&" "&C32&" "&F32&" "&D32)," ") -> 19720515 199607 04 01 70 | I32: Trenggalek | J32: 15 | K32: 05 | L32: 1972 | M32: =L32&K32&J32 -> 19720515 | N32: 17 | O32: 07 | P32: 1996 | Q32: 17 | R32: 07 | S32: 1996 | T32: =$E$4-S32 -> 29 | U32: =$E$4-P32 -> 29 | V32: =IF(U32=$E$4," ",U32) -> 29 | W32: =IF(T32=$E$4," ",T32) -> 29 | X32: S1 | Y32: Pendidikan Agama Islam | Z32: 2000 | AA32: SUDAH | AC32: =IFERROR(VLOOKUP(AD32,REFERENSI!$H$5:$I$13,2,FALSE)," ") | AE32: Aqidah, Qur'an Hadist | AG32: - | AH32: =VLOOKUP(AG32,$BK$6:$BL$19,2,FALSE) -> - | AI32: =IFERROR((AF32+AH32)," ") | AJ32: SUDAH | AK32: 2009 | AL32: 101486432014 | AM32: 9847750652200012 | BF32: 27 | BG32: 1970
A33: 30 | B33: MTs | C33: =IFERROR(VLOOKUP(B33,REFERENSI!$C$6:$D$15,2,FALSE)," ") -> 04 | D33: 73 | E33: Guru | F33: =IFERROR(VLOOKUP(E33,REFERENSI!$F$5:$G$6,2,FALSE)," ") -> 01 | G33: BAHRUN ROFIQI, S.Ag | H33: =IFERROR((M33&" "&P33&O33&" "&C33&" "&F33&" "&D33)," ") -> 19730626 199907 04 01 73 | I33: Trenggalek | J33: 26 | K33: 06 | L33: 1973 | M33: =L33&K33&J33 -> 19730626 | N33: 18 | O33: 07 | P33: 1999 | Q33: 18 | R33: 07 | S33: 1999 | T33: =$E$4-S33 -> 26 | U33: =$E$4-P33 -> 26 | V33: =IF(U33=$E$4," ",U33) -> 26 | W33: =IF(T33=$E$4," ",T33) -> 26 | X33: S1 | Y33: Pendidikan Agama Islam | Z33: 1998 | AC33: =IFERROR(VLOOKUP(AD33,REFERENSI!$H$5:$I$13,2,FALSE)," ") | AE33: Fiqih, Qur'an Hadist | AG33: - | AH33: =VLOOKUP(AG33,$BK$6:$BL$19,2,FALSE) -> - | AI33: =IFERROR((AF33+AH33)," ") | AJ33: SUDAH | AK33: 2011 | AL33: 112372126016 | AM33: 0958751653200012 | BF33: 28 | BG33: 1971
A34: 31 | B34: SMK 2 | C34: =IFERROR(VLOOKUP(B34,REFERENSI!$C$6:$D$15,2,FALSE)," ") -> 07 | D34: 15 | E34: Tenaga Kependidikan | F34: =IFERROR(VLOOKUP(E34,REFERENSI!$F$5:$G$6,2,FALSE)," ") -> 02 | G34: ZAYYINA BINTANG NURDIANA YUSUF | H34: =IFERROR((M34&" "&P34&O34&" "&C34&" "&F34&" "&D34)," ") -> 20040301 202407 07 02 15 | I34: Trenggalek | J34: 01 | K34: 03 | L34: 2004 | M34: =L34&K34&J34 -> 20040301 | N34: 15 | O34: 07 | P34: 2024 | Q34: 15 | R34: 07 | S34: 2024 | T34: =$E$4-S34 -> 1 | U34: =$E$4-P34 -> 1 | V34: =IF(U34=$E$4," ",U34) -> 1 | W34: =IF(T34=$E$4," ",T34) -> 1 | X34: SLTA | Y34: IPS | Z34: 2001 | AA34: SUDAH | AC34: =IFERROR(VLOOKUP(AD34,REFERENSI!$H$5:$I$13,2,FALSE)," ") | AE34: Bahasa Arab | AG34: - | AH34: =VLOOKUP(AG34,$BK$6:$BL$19,2,FALSE) -> - | AI34: =IFERROR((AF34+AH34)," ") | AJ34: SUDAH | AL34: 122392148017 | AM34: 7445751654200003 | BF34: 29 | BG34: 1972
A35: 32 | B35: MTs | C35: =IFERROR(VLOOKUP(B35,REFERENSI!$C$6:$D$15,2,FALSE)," ") -> 04 | D35: 29 | E35: Guru | F35: =IFERROR(VLOOKUP(E35,REFERENSI!$F$5:$G$6,2,FALSE)," ") -> 01 | G35: DWI PURWATININGSIH, S.Pd | H35: =IFERROR((M35&" "&P35&O35&" "&C35&" "&F35&" "&D35)," ") -> 19810709 200407 04 01 29 | I35: Trenggalek | J35: 09 | K35: 07 | L35: 1981 | M35: =L35&K35&J35 -> 19810709 | N35: 18 | O35: 07 | P35: 2004 | Q35: 18 | R35: 07 | S35: 2004 | T35: =$E$4-S35 -> 21 | U35: =$E$4-P35 -> 21 | V35: =IF(U35=$E$4," ",U35) -> 21 | W35: =IF(T35=$E$4," ",T35) -> 21 | X35: S1 | Y35: Pendidikan Matematika | Z35: 2004 | AC35: =IFERROR(VLOOKUP(AD35,REFERENSI!$H$5:$I$13,2,FALSE)," ") | AE35: Matematika | AG35: - | AH35: =VLOOKUP(AG35,$BK$6:$BL$19,2,FALSE) -> - | AI35: =IFERROR((AF35+AH35)," ") | AJ35: SUDAH | AK35: 2010 | AL35: 091688472004 | AM35: 7041759661300013 | BF35: 30 | BG35: 1973
A36: 33 | B36: MTs | C36: =IFERROR(VLOOKUP(B36,REFERENSI!$C$6:$D$15,2,FALSE)," ") -> 04 | D36: 80 | E36: Guru | F36: =IFERROR(VLOOKUP(E36,REFERENSI!$F$5:$G$6,2,FALSE)," ") -> 01 | G36: BANGKIT ADI SWASONO, M.Pd | H36: =IFERROR((M36&" "&P36&O36&" "&C36&" "&F36&" "&D36)," ") -> 19810520 200207 04 01 80 | I36: Trenggalek | J36: 20 | K36: 05 | L36: 1981 | M36: =L36&K36&J36 -> 19810520 | N36: 17 | O36: 07 | P36: 2002 | Q36: 17 | R36: 07 | S36: 2002 | T36: =$E$4-S36 -> 23 | U36: =$E$4-P36 -> 23 | V36: =IF(U36=$E$4," ",U36) -> 23 | W36: =IF(T36=$E$4," ",T36) -> 23 | X36: S2 | Y36: Pendidikan Bahasa Indonesia | Z36: 2007 | AC36: =IFERROR(VLOOKUP(AD36,REFERENSI!$H$5:$I$13,2,FALSE)," ") | AE36: Bahasa Indonesia | AG36: - | AH36: =VLOOKUP(AG36,$BK$6:$BL$19,2,FALSE) -> - | AI36: =IFERROR((AF36+AH36)," ") | AJ36: SUDAH | AK36: 2009 | AL36: 101488977005 | AM36: 1852759661200012 | BF36: 31 | BG36: 1974
A37: 34 | B37: MTs | C37: =IFERROR(VLOOKUP(B37,REFERENSI!$C$6:$D$15,2,FALSE)," ") -> 04 | D37: 83 | E37: Guru | F37: =IFERROR(VLOOKUP(E37,REFERENSI!$F$5:$G$6,2,FALSE)," ") -> 01 | G37: SITI NUR'ALIYAH, S.Pd.I | H37: =IFERROR((M37&" "&P37&O37&" "&C37&" "&F37&" "&D37)," ") -> 19780220 200307 04 01 83 | I37: Bandung Baru | J37: 20 | K37: 02 | L37: 1978 | M37: =L37&K37&J37 -> 19780220 | N37: 18 | O37: 07 | P37: 2003 | Q37: 18 | R37: 07 | S37: 2003 | T37: =$E$4-S37 -> 22 | U37: =$E$4-P37 -> 22 | V37: =IF(U37=$E$4," ",U37) -> 22 | W37: =IF(T37=$E$4," ",T37) -> 22 | X37: S1 | Y37: Pendidikan Agama Islam | Z37: 2002 | AA37: SUDAH | AC37: =IFERROR(VLOOKUP(AD37,REFERENSI!$H$5:$I$13,2,FALSE)," ") | AE37: IPS | AG37: - | AH37: =VLOOKUP(AG37,$BK$6:$BL$19,2,FALSE) -> - | AI37: =IFERROR((AF37+AH37)," ") | AJ37: SUDAH | AK37: 2011 | AL37: 111002188003 | AM37: 4552756657300022 | BG37: 1975
A38: 35 | B38: MTs | C38: =IFERROR(VLOOKUP(B38,REFERENSI!$C$6:$D$15,2,FALSE)," ") -> 04 | D38: 21 | E38: Guru | F38: =IFERROR(VLOOKUP(E38,REFERENSI!$F$5:$G$6,2,FALSE)," ") -> 01 | G38: SITI NURSIYAH, S.Pd | H38: =IFERROR((M38&" "&P38&O38&" "&C38&" "&F38&" "&D38)," ") -> 19780615 200207 04 01 21 | I38: Trenggalek | J38: 15 | K38: 06 | L38: 1978 | M38: =L38&K38&J38 -> 19780615 | N38: 17 | O38: 07 | P38: 2002 | Q38: 17 | R38: 07 | S38: 2002 | T38: =$E$4-S38 -> 23 | U38: =$E$4-P38 -> 23 | V38: =IF(U38=$E$4," ",U38) -> 23 | W38: =IF(T38=$E$4," ",T38) -> 23 | X38: S1 | Y38: Pendidikan Bahasa Inggris | Z38: 2002 | AA38: SUDAH | AC38: =IFERROR(VLOOKUP(AD38,REFERENSI!$H$5:$I$13,2,FALSE)," ") | AE38: Bahasa Inggris | AG38: - | AH38: =VLOOKUP(AG38,$BK$6:$BL$19,2,FALSE) -> - | AI38: =IFERROR((AF38+AH38)," ") | AJ38: SUDAH | AK38: 2009 | AL38: 091987957011 | AM38: 3947756657300012 | BG38: 1976
A39: 36 | B39: MTs | C39: =IFERROR(VLOOKUP(B39,REFERENSI!$C$6:$D$15,2,FALSE)," ") -> 04 | D39: 95 | E39: Guru | F39: =IFERROR(VLOOKUP(E39,REFERENSI!$F$5:$G$6,2,FALSE)," ") -> 01 | G39: ALI MASKUR, S.Pd.I | H39: =IFERROR((M39&" "&P39&O39&" "&C39&" "&F39&" "&D39)," ") -> 19850828 200507 04 01 95 | I39: Trenggalek | J39: 28 | K39: 08 | L39: 1985 | M39: =L39&K39&J39 -> 19850828 | N39: 18 | O39: 07 | P39: 2005 | Q39: 18 | R39: 07 | S39: 2005 | T39: =$E$4-S39 -> 20 | U39: =$E$4-P39 -> 20 | V39: =IF(U39=$E$4," ",U39) -> 20 | W39: =IF(T39=$E$4," ",T39) -> 20 | X39: S1 | Y39: Pendidikan Agama Islam | Z39: 2009 | AC39: =IFERROR(VLOOKUP(AD39,REFERENSI!$H$5:$I$13,2,FALSE)," ") | AE39: TIK | AF39: 22 | AG39: Kepala Perpustakaan | AH39: =VLOOKUP(AG39,$BK$6:$BL$19,2,FALSE) -> 12 | AI39: =IFERROR((AF39+AH39)," ") -> 34 | AJ39: SUDAH | AK39: 2012 | AL39: 122242188011 | AM39: 1160763666200003 | BG39: 1977
A40: 37 | B40: MTs | C40: =IFERROR(VLOOKUP(B40,REFERENSI!$C$6:$D$15,2,FALSE)," ") -> 04 | D40: 89 | E40: Guru | F40: =IFERROR(VLOOKUP(E40,REFERENSI!$F$5:$G$6,2,FALSE)," ") -> 01 | G40: FARHATUN NADHIROH, S.Si | H40: =IFERROR((M40&" "&P40&O40&" "&C40&" "&F40&" "&D40)," ") -> 19800201 200407 04 01 89 | I40: Madiun | J40: 01 | K40: 02 | L40: 1980 | M40: =L40&K40&J40 -> 19800201 | N40: 19 | O40: 07 | P40: 2004 | Q40: 19 | R40: 07 | S40: 2004 | T40: =$E$4-S40 -> 21 | U40: =$E$4-P40 -> 21 | V40: =IF(U40=$E$4," ",U40) -> 21 | W40: =IF(T40=$E$4," ",T40) -> 21 | X40: S1 | Y40: KIMIA | Z40: 2003 | AC40: =IFERROR(VLOOKUP(AD40,REFERENSI!$H$5:$I$13,2,FALSE)," ") | AE40: IPA | AF40: 30 | AG40: - | AH40: =VLOOKUP(AG40,$BK$6:$BL$19,2,FALSE) -> - | AI40: =IFERROR((AF40+AH40)," ") | AJ40: SUDAH | AK40: 2010 | AL40: 021285967011 | AM40: 0533758659210152 | BG40: 1978
A41: 38 | B41: MTs | C41: =IFERROR(VLOOKUP(B41,REFERENSI!$C$6:$D$15,2,FALSE)," ") -> 04 | D41: 34 | E41: Guru | F41: =IFERROR(VLOOKUP(E41,REFERENSI!$F$5:$G$6,2,FALSE)," ") -> 01 | G41: AGUNG BUDI SUSILO, S.Pd | H41: =IFERROR((M41&" "&P41&O41&" "&C41&" "&F41&" "&D41)," ") -> 19811001 200507 04 01 34 | I41: Trenggalek | J41: 01 | K41: 10 | L41: 1981 | M41: =L41&K41&J41 -> 19811001 | N41: 18 | O41: 07 | P41: 2005 | Q41: 18 | R41: 07 | S41: 2005 | T41: =$E$4-S41 -> 20 | U41: =$E$4-P41 -> 20 | V41: =IF(U41=$E$4," ",U41) -> 20 | W41: =IF(T41=$E$4," ",T41) -> 20 | X41: S1 | Y41: Penjaskesrek | Z41: 2010 | AC41: =IFERROR(VLOOKUP(AD41,REFERENSI!$H$5:$I$13,2,FALSE)," ") | AE41: Penjaskes | AF41: 22 | AG41: - | AH41: =VLOOKUP(AG41,$BK$6:$BL$19,2,FALSE) -> - | AI41: =IFERROR((AF41+AH41)," ") | AJ41: SUDAH | AK41: 2013 | AL41: 132202183003 | AM41: 9442759661200022 | BG41: 1979
...

Sheet REFERENSI
C5: SATKER | D5: KODE | F5: Guru | G5: 01 | H5: III A | I5: PENATA MUDA | L5: 1
C6: PAUD | D6: 01 | F6: Tenaga Kependidikan | G6: 02 | H6: III B | I6: PENATA MUDA TK. I | L6: 2
C7: RA | D7: 02 | H7: III C | I7: PENATA | L7: 3
C8: MI | D8: 03 | H8: III D | I8: PENATA TK. I | L8: 4
C9: MTs | D9: 04 | H9: IV A | I9: PEMBINA | L9: 5
C10: MA | D10: 05 | H10: IV B | I10: PEMBINA TK. I | L10: 6
C11: SMK 1 | D11: 06 | H11: IV C | I11: PEMBINA UTAMA | L11: 7
C12: SMK 2 | D12: 07 | H12: IV D | I12: PEMBINA UTAMA TK. I | L12: 8
C13: MTM | D13: 08 | H13: IV E | I13: PEMBINA UTAMA II | L13: 9
C14: TPQ | D14: 09 | L14: 10
C15: MTM 2 | D15: 10 | L15: 11
L16: 12
L17: 13
L18: 14
L19: 15
L20: 16
L21: 17
L22: 18
L23: 19
L24: 20
L25: 21
L26: 22
L27: 23
... L31: 27
B32: NOMOR SK | L32: 28
L33: 29
B34: KODE YP | C34: KODE | D34: SATKER | E34: NOMOR URUT | F34: REGRISTRASI | L34: 30
B35: YPP.QH | C35: KP.00 | D35: 2 | L35: 31

Sheet BIODATA
B1: Pilih Nama Guru Yayasan
C4: 1
D8: YAYASAN PONDOK PESANTREN
D9: QOMARUL HIDAYAH TRENGGALEK
D10: AKTE NOTARIS: KAYUN WIDIHARSONO,S.H,M.Kn NOMOR: 09 TAHUN 2014
D11: SK MENKUMHAN RI NOMOR: C-598.HT.03.01-2014
D12: ALAMAT : JL. PONOROGO, GONDANG, TUGU,TRENGGALEK KP. 66352 TELP. (0355) 792631
B15: BIODATA SINGKAT PERSONALIA
B17: NAMA | F17: : | G17: =VLOOKUP($C$4,REKAP!$C$8:$AQ$45,7,FALSE) -> Hj.AZ.MUTIATUN,A.Ma | N17: Foto 3x4
B18: NIGY | F18: : | G18: =VLOOKUP($C$4,REKAP!$C$8:$AQ$45,8,FALSE) -> 19410413 200107 02 01
B19: NUPTK | F19: : | G19: =VLOOKUP($C$4,REKAP!$C$8:$AQ$45,41,FALSE) -> -
B20: Tempat dan Tanggal Lahir | F20: : | G20: =VLOOKUP($C$4,REKAP!$C$8:$AQ$45,13,FALSE) -> Trenggalek, 13-04-1941
B21: Pendidikan terakhir / Jurusan | F21: : | G21: =VLOOKUP($C$4,REKAP!$C$8:$AQ$45,26,FALSE) -> D II | I21: / | J21: =VLOOKUP($C$4,REKAP!$C$8:$AQ$45,27,FALSE) -> PAI
B22: Status | F22: : | G22: =VLOOKUP($C$4,REKAP!$C$8:$AQ$45,5,FALSE) -> Guru
B23: TMT di Yayasan | F23: : | G23: =VLOOKUP($C$4,REKAP!$C$8:$AQ$45,17,FALSE) -> 01-07-2001
B24: Satuan kerja | F24: : | G24: =VLOOKUP($C$4,REKAP!$C$8:$AQ$45,2,FALSE) -> RA Qomarul Hidayah
B25: TMT di SATKER | F25: : | G25: =VLOOKUP($C$4,REKAP!$C$8:$AQ$45,21,FALSE) -> 01-07-2001
B26: Masa Kerja Seluruhnya | F26: : | G26: =VLOOKUP($C$4,REKAP!$C$8:$AQ$45,24,FALSE) -> 24 | H26: Tahun
B27: Masa Kerja di SATKER | F27: : | G27: =VLOOKUP($C$4,REKAP!$C$8:$AQ$45,25,FALSE) -> 24 | H27: Tahun
B28: Status Inpassing | F28: : | G28: =VLOOKUP($C$4,REKAP!$C$8:$AQ$45,29,FALSE) -> BELUM
B29: Jabatan | F29: : | G29: =VLOOKUP($C$4,REKAP!$C$8:$AQ$45,30,FALSE) -> 0
B30: Pangkat | F30: : | G30: =VLOOKUP($C$4,REKAP!$C$8:$AQ$45,31,FALSE)
B31: Golongan | F31: : | G31: =VLOOKUP($C$4,REKAP!$C$8:$AQ$45,32,FALSE) -> 0
B32: Tugas Utama Mengajar | F32: : | G32: =VLOOKUP($C$4,REKAP!$C$8:$AQ$45,33,FALSE) -> Guru Kelas
B33: Jumlah beban Kerja | F33: : | G33: =VLOOKUP($C$4,REKAP!$C$8:$AQ$45,34,FALSE) -> 0 | H33: JTM / Minggu
B34: Tugas Tambahan | F34: : | G34: =VLOOKUP($C$4,REKAP!$C$8:$AQ$45,35,FALSE) -> Kepala Sekolah
B35: Status Sertifikasi | F35: : | G35: =VLOOKUP($C$4,REKAP!$C$8:$AQ$45,38,FALSE) -> BELUM
B36: Tahun Lulus | F36: : | G36: =VLOOKUP($C$4,REKAP!$C$8:$AQ$45,39,FALSE) -> 0
B37: NRG | F37: : | G37: =VLOOKUP($C$4,REKAP!$C$8:$AQ$45,40,FALSE) -> 0
J38: An. Ketua Yayasan
J39: Kepala Bidang Personalia dan SDM
J42: ………………………………………

Sheet REKAP
C2: 1 | D2: 2 | E2: 3 | F2: 4 | G2: 5 | H2: 6 | I2: 7 | J2: 8 | K2: 9 | L2: 10 | M2: 11 | N2: 12 | O2: 13 | P2: 14 | Q2: 15 | R2: 16 | S2: 17 | T2: 18 | U2: 19 | V2: 20 | W2: 21 | X2: 22 | Y2: 23 | Z2: 24 | AA2: 25 | AB2: 26 | AC2: 27 | AD2: 28 | AE2: 29 | AF2: 30 | AG2: 31 | AH2: 32 | AI2: 33 | AJ2: 34 | AK2: 35 | AL2: 36 | AM2: 37 | AN2: 38 | AO2: 39 | AP2: 40 | AQ2: 41
B4: 1 | C4: 2 | D4: 3 | E4: 4 | F4: 5 | G4: 6 | H4: 7 | I4: 8 | J4: 9 | K4: 10 | L4: 11 | M4: 12 | N4: 13 | O4: 14 | P4: 15 | Q4: 16 | R4: 17 | S4: 18 | T4: 19 | U4: 20 | V4: 21 | W4: 22 | X4: 23 | Y4: 24 | Z4: 25 | AA4: 26 | AB4: 27 | AC4: 28 | AD4: 29 | AE4: 30 | AF4: 31 | AG4: 32 | AH4: 33 | AI4: 34 | AJ4: 35 | AK4: 36 | AL4: 37 | AM4: 38 | AN4: 39 | AO4: 40 | AP4: 41 | AQ4: 42 | AR4: 43 | AS4: 44
C5: NO | D5: SATKER | E5: KODE | F5: DUK | G5: STATUS | H5: KODE | I5: NAMA | J5: NIGY | K5: TEMPAT TANGGAL LAHIR | Z5: MASA KERJA | AB5: PENDIDIKAN TERAKIR | AE5: INPASSING | AI5: TUGAS UTAMA | AN5: SERTIFIKASI | AQ5: NUPTK | AR5: REG | AS5: NOMOR SK
P6: TMT YAYASAN | T6: TMT SATKER | Z6: SELURUHNYA (TAHUN0 | AA6: DI SATKER (TAHUN)
K7: TEMPAT | L7: TANGGAL | M7: BULAN | N7: TAHUN | P7: Tanggal | Q7: Bulan | R7: Tahun | T7: Tanggal | U7: Bulan | V7: Tahun | X7: Tahun | Y7: Tahun | AB7: JENJANG | AC7: JURUSAN | AD7: TAHUN LULUS | AE7: STATUS | AF7: JABATAN | AG7: PANGKAT | AH7: GOLONGAN | AI7: MENGAJAR | AJ7: JTM | AK7: TUGAS TAMBAHAN | AL7: EKUIVALEN | AM7: JML BEBAN KERJA | AN7: STATUS | AO7: TAHUN LULUS | AP7: NRG | AT7: kk
A8: =IF(B8=0," ",RANK(B8,$B$8:$B$178,1)) -> 21 | B8: =R8-Q8 -> 1994 | C8: 1 | D8: =IFERROR(IF(ENTRI!B8=$AZ$9,$BA$9,IF(ENTRI!B8=$AZ$10,$BA$10,IF(ENTRI!B8=$AZ$11,$BA$11,IF(ENTRI!B8=$AZ$12,$BA$12,IF(ENTRI!B8=$AZ$13,$BA$13,IF(ENTRI!B8=$AZ$14,$BA$14,IF(ENTRI!B8=$AZ$15,$BA$15,IF(ENTRI!B8=$AZ$16,$BA$16,IF(ENTRI!B8=$AZ$17,$BA$17,IF(ENTRI!B8=$AZ$18,$BA$18," "))))))))))," ") -> RA Qomarul Hidayah | E8: =IFERROR((ENTRI!C8)," ") -> 02 | F8: =A8 -> 21 | G8: =IFERROR((ENTRI!E8)," ") -> Guru | H8: =IFERROR((ENTRI!F8)," ") -> 01 | I8: =IFERROR((ENTRI!G8)," ") -> Hj.AZ.MUTIATUN,A.Ma | J8: =IFERROR((ENTRI!H8)," ") -> 19410413 200107 02 01 | K8: =IFERROR((ENTRI!I8)," ") -> Trenggalek | L8: =IFERROR((ENTRI!J8)," ") -> 13 | M8: =IFERROR((ENTRI!K8)," ") -> 04 | N8: =IFERROR((ENTRI!L8)," ") -> 1941 | O8: =K8&","&" "&L8&"-"&M8&"-"&N8 -> Trenggalek, 13-04-1941 | P8: =IFERROR((ENTRI!N8)," ") -> 01 | Q8: =IFERROR((ENTRI!O8)," ") -> 07 | R8: =IFERROR((ENTRI!P8)," ") -> 2001 | S8: =P8&"-"&Q8&"-"&R8 -> 01-07-2001 | T8: =IFERROR((ENTRI!Q8)," ") -> 01 | U8: =IFERROR((ENTRI!R8)," ") -> 07 | V8: =IFERROR((ENTRI!S8)," ") -> 2001 | W8: =T8&"-"&U8&"-"&V8 -> 01-07-2001 | X8: =IFERROR((ENTRI!T8)," ") -> 24 | Y8: =IFERROR((ENTRI!U8)," ") -> 24 | Z8: =IFERROR((ENTRI!V8)," ") -> 24 | AA8: =IFERROR((ENTRI!W8)," ") -> 24 | AB8: =IFERROR((ENTRI!X8)," ") -> D II | AC8: =IFERROR((ENTRI!Y8)," ") -> PAI | AD8: =IFERROR((ENTRI!Z8)," ") -> 1995 | AE8: =IFERROR((ENTRI!AA8)," ") -> BELUM | ... AQ8: =IFERROR((ENTRI!AM8)," ") -> - | AR8: =E8&"."&H8&"."&AW8&"."&ENTRI!$E$4 -> 02.01.001.2025 | AS8: ="YPP.QH/KP.01."&E8&"/"&AW8&"/"&ENTRI!$E$4 -> YPP.QH/KP.01.02/001/2025 | AT8: =IF(E8=2,2,IF(E8=3,3,IF(E8=4,4,IF(E8=5,5,IF(E8=6,6,7))))) -> 7 | AW8: 001
A9: =IF(B9=0," ",RANK(B9,$B$8:$B$178,1)) -> 27 | B9: =R9-Q9 -> 1996 | C9: 2 | D9: =IFERROR(IF(ENTRI!B9=$AZ$9,$BA$9,IF(ENTRI!B9=$AZ$10,$BA$10,IF(ENTRI!B9=$AZ$11,$BA$11,IF(ENTRI!B9=$AZ$12,$BA$12,IF(ENTRI!B9=$AZ$13,$BA$13,IF(ENTRI!B9=$AZ$14,$BA$14,IF(ENTRI!B9=$AZ$15,$BA$15,IF(ENTRI!B9=$AZ$16,$BA$16,IF(ENTRI!B9=$AZ$17,$BA$17,IF(ENTRI!B9=$AZ$18,$BA$18," "))))))))))," ") -> RA Qomarul Hidayah | E9: =IFERROR((ENTRI!C9)," ") -> 02 | F9: =A9 -> 27 | G9: =IFERROR((ENTRI!E9)," ") -> Guru | H9: =IFERROR((ENTRI!F9)," ") -> 01 | I9: =IFERROR((ENTRI!G9)," ") -> RINA WIJAYANTI,S.Pd.I | J9: =IFERROR((ENTRI!H9)," ") -> 19850425 200307 02 01 | K9: =IFERROR((ENTRI!I9)," ") -> Trenggalek | L9: =IFERROR((ENTRI!J9)," ") -> 25 | M9: =IFERROR((ENTRI!K9)," ") -> 04 | N9: =IFERROR((ENTRI!L9)," ") -> 1985 | O9: =K9&","&" "&L9&"-"&M9&"-"&N9 -> Trenggalek, 25-04-1985 | P9: =IFERROR((ENTRI!N9)," ") -> 01 | Q9: =IFERROR((ENTRI!O9)," ") -> 07 | R9: =IFERROR((ENTRI!P9)," ") -> 2003 | S9: =P9&"-"&Q9&"-"&R9 -> 01-07-2003 | T9: =IFERROR((ENTRI!Q9)," ") -> 01 | U9: =IFERROR((ENTRI!R9)," ") -> 07 | V9: =IFERROR((ENTRI!S9)," ") -> 2003 | W9: =T9&"-"&U9&"-"&V9 -> 01-07-2003 | X9: =IFERROR((ENTRI!T9)," ") -> 22 | Y9: =IFERROR((ENTRI!U9)," ") -> 22 | Z9: =IFERROR((ENTRI!V9)," ") -> 22 | AA9: =IFERROR((ENTRI!W9)," ") -> 22 | AB9: =IFERROR((ENTRI!X9)," ") -> S1 | AC9: =IFERROR((ENTRI!Y9)," ") -> PAI | AD9: =IFERROR((ENTRI!Z9)," ") -> 2008 | AE9: =IFERROR((ENTRI!AA9)," ") -> SUDAH | ... AQ9: =IFERROR((ENTRI!AM9)," ") -> 4757763664300032 | AR9: =E9&"."&H9&"."&AW9&"."&ENTRI!$E$4 -> 02.01.002.2025 | AS9: ="YPP.QH/KP.01."&E9&"/"&AW9&"/"&ENTRI!$E$4 -> YPP.QH/KP.01.02/002/2025 | AW9: 002 | AZ9: PAUD | BA9: PAUD Qomarul Hidayah
A10: =IF(B10=0," ",RANK(B10,$B$8:$B$178,1)) -> 75 | B10: =R10-Q10 -> 2004 | C10: 3 | D10: =IFERROR(IF(ENTRI!B10=$AZ$9,$BA$9,IF(ENTRI!B10=$AZ$10,$BA$10,IF(ENTRI!B10=$AZ$11,$BA$11,IF(ENTRI!B10=$AZ$12,$BA$12,IF(ENTRI!B10=$AZ$13,$BA$13,IF(ENTRI!B10=$AZ$14,$BA$14,IF(ENTRI!B10=$AZ$15,$BA$15,IF(ENTRI!B10=$AZ$16,$BA$16,IF(ENTRI!B10=$AZ$17,$BA$17,IF(ENTRI!B10=$AZ$18,$BA$18," "))))))))))," ") -> RA Qomarul Hidayah | E10: =IFERROR((ENTRI!C10)," ") -> 02 | F10: =A10 -> 75 | G10: =IFERROR((ENTRI!E10)," ") -> Guru | H10: =IFERROR((ENTRI!F10)," ") -> 01 | I10: =IFERROR((ENTRI!G10)," ") -> HIDAYATUL LAILI,S.Ag | J10: =IFERROR((ENTRI!H10)," ") -> 19731025 200501 02 01 | K10: =IFERROR((ENTRI!I10)," ") -> Trenggalek | L10: =IFERROR((ENTRI!J10)," ") -> 25 | M10: =IFERROR((ENTRI!K10)," ") -> 10 | N10: =IFERROR((ENTRI!L10)," ") -> 1973 | O10: =K10&","&" "&L10&"-"&M10&"-"&N10 -> Trenggalek, 25-10-1973 | P10: =IFERROR((ENTRI!N10)," ") -> 02 | Q10: =IFERROR((ENTRI!O10)," ") -> 01 | R10: =IFERROR((ENTRI!P10)," ") -> 2005 | S10: =P10&"-"&Q10&"-"&R10 -> 02-01-2005 | T10: =IFERROR((ENTRI!Q10)," ") -> 02 | U10: =IFERROR((ENTRI!R10)," ") -> 01 | V10: =IFERROR((ENTRI!S10)," ") -> 2005 | W10: =T10&"-"&U10&"-"&V10 -> 02-01-2005 | X10: =IFERROR((ENTRI!T10)," ") -> 20 | Y10: =IFERROR((ENTRI!U10)," ") -> 20 | Z10: =IFERROR((ENTRI!V10)," ") -> 20 | AA10: =IFERROR((ENTRI!W10)," ") -> 20 | AB10: =IFERROR((ENTRI!X10)," ") -> S1 | AC10: =IFERROR((ENTRI!Y10)," ") -> PAI | AD10: =IFERROR((ENTRI!Z10)," ") -> 1995 | AE10: =IFERROR((ENTRI!AA10)," ") -> SUDAH | ... AQ10: =IFERROR((ENTRI!AM10)," ") -> 1357751652300013 | AR10: =E10&"."&H10&"."&AW10&"."&ENTRI!$E$4 -> 02.01.003.2025 | AS10: ="YPP.QH/KP.01."&E10&"/"&AW10&"/"&ENTRI!$E$4 -> YPP.QH/KP.01.02/003/2025 | AW10: 003 | AZ10: RA | BA10: RA Qomarul Hidayah
A11: =IF(B11=0," ",RANK(B11,$B$8:$B$178,1)) -> 50 | B11: =R11-Q11 -> 1999 | C11: 4 | D11: =IFERROR(IF(ENTRI!B11=$AZ$9,$BA$9,IF(ENTRI!B11=$AZ$10,$BA$10,IF(ENTRI!B11=$AZ$11,$BA$11,IF(ENTRI!B11=$AZ$12,$BA$12,IF(ENTRI!B11=$AZ$13,$BA$13,IF(ENTRI!B11=$AZ$14,$BA$14,IF(ENTRI!B11=$AZ$15,$BA$15,IF(ENTRI!B11=$AZ$16,$BA$16,IF(ENTRI!B11=$AZ$17,$BA$17,IF(ENTRI!B11=$AZ$18,$BA$18," "))))))))))," ") -> RA Qomarul Hidayah | E11: =IFERROR((ENTRI!C11)," ") -> 02 | F11: =A11 -> 50 | G11: =IFERROR((ENTRI!E11)," ") -> Guru | H11: =IFERROR((ENTRI!F11)," ") -> 01 | I11: =IFERROR((ENTRI!G11)," ") -> RENI FARICHA ARIANI,S.Pd.I | J11: =IFERROR((ENTRI!H11)," ") -> 19850116 200607 02 01 | K11: =IFERROR((ENTRI!I11)," ") -> Trenggalek | L11: =IFERROR((ENTRI!J11)," ") -> 16 | M11: =IFERROR((ENTRI!K11)," ") -> 01 | N11: =IFERROR((ENTRI!L11)," ") -> 1985 | O11: =K11&","&" "&L11&"-"&M11&"-"&N11 -> Trenggalek, 16-01-1985 | P11: =IFERROR((ENTRI!N11)," ") -> 01 | Q11: =IFERROR((ENTRI!O11)," ") -> 07 | R11: =IFERROR((ENTRI!P11)," ") -> 2006 | S11: =P11&"-"&Q11&"-"&R11 -> 01-07-2006 | T11: =IFERROR((ENTRI!Q11)," ") -> 01 | U11: =IFERROR((ENTRI!R11)," ") -> 07 | V11: =IFERROR((ENTRI!S11)," ") -> 2006 | W11: =T11&"-"&U11&"-"&V11 -> 01-07-2006 | X11: =IFERROR((ENTRI!T11)," ") -> 19 | Y11: =IFERROR((ENTRI!U11)," ") -> 19 | Z11: =IFERROR((ENTRI!V11)," ") -> 19 | AA11: =IFERROR((ENTRI!W11)," ") -> 19 | AB11: =IFERROR((ENTRI!X11)," ") -> S1 | AC11: =IFERROR((ENTRI!Y11)," ") -> PGMI | AD11: =IFERROR((ENTRI!Z11)," ") -> 2012 | AE11: =IFERROR((ENTRI!AA11)," ") -> BELUM | ... AQ11: =IFERROR((ENTRI!AM11)," ") -> 3448763664300032 | AR11: =E11&"."&H11&"."&AW11&"."&ENTRI!$E$4 -> 02.01.004.2025 | AS11: ="YPP.QH/KP.01."&E11&"/"&AW11&"/"&ENTRI!$E$4 -> YPP.QH/KP.01.02/004/2025 | AW11: 004 | AZ11: MI | BA11: MI Qomarul Hidayah
A12: =IF(B12=0," ",RANK(B12,$B$8:$B$178,1)) -> 53 | B12: =R12-Q12 -> 2000 | C12: 5 | D12: =IFERROR(IF(ENTRI!B12=$AZ$9,$BA$9,IF(ENTRI!B12=$AZ$10,$BA$10,IF(ENTRI!B12=$AZ$11,$BA$11,IF(ENTRI!B12=$AZ$12,$BA$12,IF(ENTRI!B12=$AZ$13,$BA$13,IF(ENTRI!B12=$AZ$14,$BA$14,IF(ENTRI!B12=$AZ$15,$BA$15,IF(ENTRI!B12=$AZ$16,$BA$16,IF(ENTRI!B12=$AZ$17,$BA$17,IF(ENTRI!B12=$AZ$18,$BA$18," "))))))))))," ") -> PAUD Qomarul Hidayah | E12: =IFERROR((ENTRI!C12)," ") -> 01 | F12: =A12 -> 53 | G12: =IFERROR((ENTRI!E12)," ") -> Guru | H12: =IFERROR((ENTRI!F12)," ") -> 01 | I12: =IFERROR((ENTRI!G12)," ") -> ISTIQOMAH | J12: =IFERROR((ENTRI!H12)," ") -> 19830614 200707 01 01 | K12: =IFERROR((ENTRI!I12)," ") -> Trenggalek | L12: =IFERROR((ENTRI!J12)," ") -> 14 | M12: =IFERROR((ENTRI!K12)," ") -> 06 | N12: =IFERROR((ENTRI!L12)," ") -> 1983 | O12: =K12&","&" "&L12&"-"&M12&"-"&N12 -> Trenggalek, 14-06-1983 | P12: =IFERROR((ENTRI!N12)," ") -> 16 | Q12: =IFERROR((ENTRI!O12)," ") -> 07 | R12: =IFERROR((ENTRI!P12)," ") -> 2007 | S12: =P12&"-"&Q12&"-"&R12 -> 16-07-2007 | T12: =IFERROR((ENTRI!Q12)," ") -> 16 | U12: =IFERROR((ENTRI!R12)," ") -> 07 | V12: =IFERROR((ENTRI!S12)," ") -> 2007 | W12: =T12&"-"&U12&"-"&V12 -> 16-07-2007 | X12: =IFERROR((ENTRI!T12)," ") -> 18 | Y12: =IFERROR((ENTRI!U12)," ") -> 18 | Z12: =IFERROR((ENTRI!V12)," ") -> 18 | AA12: =IFERROR((ENTRI!W12)," ") -> 18 | AB12: =IFERROR((ENTRI!X12)," ") -> S1 | AC12: =IFERROR((ENTRI!Y12)," ") -> PAUD | AD12: =IFERROR((ENTRI!Z12)," ") -> 2002 | AE12: =IFERROR((ENTRI!AA12)," ") -> BELUM | ... AQ12: =IFERROR((ENTRI!AM12)," ") -> 1641746650300012 | AR12: =E12&"."&H12&"."&AW12&"."&ENTRI!$E$4 -> 01.01.005.2025 | AS12: ="YPP.QH/KP.01."&E12&"/"&AW12&"/"&ENTRI!$E$4 -> YPP.QH/KP.01.01/005/2025 | AW12: 005 | AZ12: MTS | BA12: MTs Qomarul Hidayah
A13: =IF(B13=0," ",RANK(B13,$B$8:$B$178,1)) -> 60 | B13: =R13-Q13 -> 2001 | C13: 6 | D13: =IFERROR(IF(ENTRI!B13=$AZ$9,$BA$9,IF(ENTRI!B13=$AZ$10,$BA$10,IF(ENTRI!B13=$AZ$11,$BA$11,IF(ENTRI!B13=$AZ$12,$BA$12,IF(ENTRI!B13=$AZ$13,$BA$13,IF(ENTRI!B13=$AZ$14,$BA$14,IF(ENTRI!B13=$AZ$15,$BA$15,IF(ENTRI!B13=$AZ$16,$BA$16,IF(ENTRI!B13=$AZ$17,$BA$17,IF(ENTRI!B13=$AZ$18,$BA$18," "))))))))))," ") -> PAUD Qomarul Hidayah | E13: =IFERROR((ENTRI!C13)," ") -> 01 | F13: =A13 -> 60 | G13: =IFERROR((ENTRI!E13)," ") -> Guru | H13: =IFERROR((ENTRI!F13)," ") -> 01 | I13: =IFERROR((ENTRI!G13)," ") -> IKA SULISTIOWATI | J13: =IFERROR((ENTRI!H13)," ") -> 19851023 200807 01 01 | K13: =IFERROR((ENTRI!I13)," ") -> Trenggalek | L13: =IFERROR((ENTRI!J13)," ") -> 23 | M13: =IFERROR((ENTRI!K13)," ") -> 10 | N13: =IFERROR((ENTRI!L13)," ") -> 1985 | O13: =K13&","&" "&L13&"-"&M13&"-"&N13 -> Trenggalek, 23-10-1985 | P13: =IFERROR((ENTRI!N13)," ") -> 14 | Q13: =IFERROR((ENTRI!O13)," ") -> 07 | R13: =IFERROR((ENTRI!P13)," ") -> 2008 | S13: =P13&"-"&Q13&"-"&R13 -> 14-07-2008 | T13: =IFERROR((ENTRI!Q13)," ") -> 14 | U13: =IFERROR((ENTRI!R13)," ") -> 07 | V13: =IFERROR((ENTRI!S13)," ") -> 2008 | W13: =T13&"-"&U13&"-"&V13 -> 14-07-2008 | X13: =IFERROR((ENTRI!T13)," ") -> 17 | Y13: =IFERROR((ENTRI!U13)," ") -> 17 | Z13: =IFERROR((ENTRI!V13)," ") -> 17 | AA13: =IFERROR((ENTRI!W13)," ") -> 17 | AB13: =IFERROR((ENTRI!X13)," ") -> S1 | AC13: =IFERROR((ENTRI!Y13)," ") -> B.INGGRIS | AD13: =IFERROR((ENTRI!Z13)," ") -> 2010 | AE13: =IFERROR((ENTRI!AA13)," ") -> BELUM | ... AQ13: =IFERROR((ENTRI!AM13)," ") -> 4538757658300060 | AR13: =E13&"."&H13&"."&AW13&"."&ENTRI!$E$4 -> 01.01.006.2025 | AS13: ="YPP.QH/KP.01."&E13&"/"&AW13&"/"&ENTRI!$E$4 -> YPP.QH/KP.01.01/006/2025 | AW13: 006 | AZ13: MA | BA13: MA Qomarul Hidayah
A14: =IF(B14=0," ",RANK(B14,$B$8:$B$178,1)) -> 86 | B14: =R14-Q14 -> 2006 | C14: 7 | D14: =IFERROR(IF(ENTRI!B14=$AZ$9,$BA$9,IF(ENTRI!B14=$AZ$10,$BA$10,IF(ENTRI!B14=$AZ$11,$BA$11,IF(ENTRI!B14=$AZ$12,$BA$12,IF(ENTRI!B14=$AZ$13,$BA$13,IF(ENTRI!B14=$AZ$14,$BA$14,IF(ENTRI!B14=$AZ$15,$BA$15,IF(ENTRI!B14=$AZ$16,$BA$16,IF(ENTRI!B14=$AZ$17,$BA$17,IF(ENTRI!B14=$AZ$18,$BA$18," "))))))))))," ") -> PAUD Qomarul Hidayah | E14: =IFERROR((ENTRI!C14)," ") -> 01 | F14: =A14 -> 86 | G14: =IFERROR((ENTRI!E14)," ") -> Tenaga Kependidikan | H14: =IFERROR((ENTRI!F14)," ") -> 02 | I14: =IFERROR((ENTRI!G14)," ") -> SITI MAESAROH | J14: =IFERROR((ENTRI!H14)," ") -> 19840707 201307 01 02 | K14: =IFERROR((ENTRI!I14)," ") -> Trenggalek | L14: =IFERROR((ENTRI!J14)," ") -> 07 | M14: =IFERROR((ENTRI!K14)," ") -> 07 | N14: =IFERROR((ENTRI!L14)," ") -> 1984 | O14: =K14&","&" "&L14&"-"&M14&"-"&N14 -> Trenggalek, 07-07-1984 | P14: =IFERROR((ENTRI!N14)," ") -> 08 | Q14: =IFERROR((ENTRI!O14)," ") -> 07 | R14: =IFERROR((ENTRI!P14)," ") -> 2013 | S14: =P14&"-"&Q14&"-"&R14 -> 08-07-2013 | T14: =IFERROR((ENTRI!Q14)," ") -> 08 | U14: =IFERROR((ENTRI!R14)," ") -> 07 | V14: =IFERROR((ENTRI!S14)," ") -> 2013 | W14: =T14&"-"&U14&"-"&V14 -> 08-07-2013 | X14: =IFERROR((ENTRI!T14)," ") -> 12 | Y14: =IFERROR((ENTRI!U14)," ") -> 12 | Z14: =IFERROR((ENTRI!V14)," ") -> 12 | AA14: =IFERROR((ENTRI!W14)," ") -> 12 | AB14: =IFERROR((ENTRI!X14)," ") -> SLTA | AC14: =IFERROR((ENTRI!Y14)," ") -> SK | AD14: =IFERROR((ENTRI!Z14)," ") -> 2003 | AE14: =IFERROR((ENTRI!AA14)," ") -> BELUM | ... AQ14: =IFERROR((ENTRI!AM14)," ") -> 4433758659300190 | AR14: =E14&"."&H14&"."&AW14&"."&ENTRI!$E$4 -> 01.02.007.2025 | AS14: ="YPP.QH/KP.01."&E14&"/"&AW14&"/"&ENTRI!$E$4 -> YPP.QH/KP.01.01/007/2025 | AW14: 007 | AZ14: SMK 1 | BA14: SMK Qomarul Hidayah 1 Tugu
A15: =IF(B15=0," ",RANK(B15,$B$8:$B$178,1)) -> 12 | B15: =R15-Q15 -> 1988 | C15: 8 | D15: =IFERROR(IF(ENTRI!B15=$AZ$9,$BA$9,IF(ENTRI!B15=$AZ$10,$BA$10,IF(ENTRI!B15=$AZ$11,$BA$11,IF(ENTRI!B15=$AZ$12,$BA$12,IF(ENTRI!B15=$AZ$13,$BA$13,IF(ENTRI!B15=$AZ$14,$BA$14,IF(ENTRI!B15=$AZ$15,$BA$15,IF(ENTRI!B15=$AZ$16,$BA$16,IF(ENTRI!B15=$AZ$17,$BA$17,IF(ENTRI!B15=$AZ$18,$BA$18," "))))))))))," ") -> MI Qomarul Hidayah | E15: =IFERROR((ENTRI!C15)," ") -> 03 | F15: =A15 -> 12 | G15: =IFERROR((ENTRI!E15)," ") -> Guru | H15: =IFERROR((ENTRI!F15)," ") -> 01 | I15: =IFERROR((ENTRI!G15)," ") -> SITI CHOIRIYAH,S.Pd.I | J15: =IFERROR((ENTRI!H15)," ") -> 19680903 199507 03 01 67 | K15: =IFERROR((ENTRI!I15)," ") -> Trenggalek | L15: =IFERROR((ENTRI!J15)," ") -> 03 | M15: =IFERROR((ENTRI!K15)," ") -> 09 | N15: =IFERROR((ENTRI!L15)," ") -> 1968 | O15: =K15&","&" "&L15&"-"&M15&"-"&N15 -> Trenggalek, 03-09-1968 | P15: =IFERROR((ENTRI!N15)," ") -> 05 | Q15: =IFERROR((ENTRI!O15)," ") -> 07 | R15: =IFERROR((ENTRI!P15)," ") -> 1995 | S15: =P15&"-"&Q15&"-"&R15 -> 05-07-1995 | T15: =IFERROR((ENTRI!Q15)," ") -> 05 | U15: =IFERROR((ENTRI!R15)," ") -> 07 | V15: =IFERROR((ENTRI!S15)," ") -> 1995 | W15: =T15&"-"&U15&"-"&V15 -> 05-07-1995 | X15: =IFERROR((ENTRI!T15)," ") -> 30 | Y15: =IFERROR((ENTRI!U15)," ") -> 30 | Z15: =IFERROR((ENTRI!V15)," ") -> 30 | AA15: =IFERROR((ENTRI!W15)," ") -> 30 | AB15: =IFERROR((ENTRI!X15)," ") -> S1 | AC15: =IFERROR((ENTRI!Y15)," ") -> PAI | AD15: =IFERROR((ENTRI!Z15)," ") -> 2009 | AE15: =IFERROR((ENTRI!AA15)," ") -> SUDAH | ... AQ15: =IFERROR((ENTRI!AM15)," ") -> 6858764666200002 | AR15: =E15&"."&H15&"."&AW15&"."&ENTRI!$E$4 -> 03.01.008.2025 | AS15: ="YPP.QH/KP.01."&E15&"/"&AW15&"/"&ENTRI!$E$4 -> YPP.QH/KP.01.03/008/2025 | AW15: 008 | AZ15: SMK 2 | BA15: SMK Qomarul Hidayah 2 Tugu
A16: =IF(B16=0," ",RANK(B16,$B$8:$B$178,1)) -> 19 | B16: =R16-Q16 -> 1993 | C16: 9 | D16: =IFERROR(IF(ENTRI!B16=$AZ$9,$BA$9,IF(ENTRI!B16=$AZ$10,$BA$10,IF(ENTRI!B16=$AZ$11,$BA$11,IF(ENTRI!B16=$AZ$12,$BA$12,IF(ENTRI!B16=$AZ$13,$BA$13,IF(ENTRI!B16=$AZ$14,$BA$14,IF(ENTRI!B16=$AZ$15,$BA$15,IF(ENTRI!B16=$AZ$16,$BA$16,IF(ENTRI!B16=$AZ$17,$BA$17,IF(ENTRI!B16=$AZ$18,$BA$18," "))))))))))," ") -> MI Qomarul Hidayah | E16: =IFERROR((ENTRI!C16)," ") -> 03 | F16: =A16 -> 19 | G16: =IFERROR((ENTRI!E16)," ") -> Guru | H16: =IFERROR((ENTRI!F16)," ") -> 01 | I16: =IFERROR((ENTRI!G16)," ") -> IMMAROTUS SA'ADAH,S.Pd.I | J16: =IFERROR((ENTRI!H16)," ") -> 19790602 200007 03 01 01 | K16: =IFERROR((ENTRI!I16)," ") -> Trenggalek | L16: =IFERROR((ENTRI!J16)," ") -> 02 | M16: =IFERROR((ENTRI!K16)," ") -> 06 | N16: =IFERROR((ENTRI!L16)," ") -> 1979 | O16: =K16&","&" "&L16&"-"&M16&"-"&N16 -> Trenggalek, 02-06-1979 | P16: =IFERROR((ENTRI!N16)," ") -> 01 | Q16: =IFERROR((ENTRI!O16)," ") -> 07 | R16: =IFERROR((ENTRI!P16)," ") -> 2000 | S16: =P16&"-"&Q16&"-"&R16 -> 01-07-2000 | T16: =IFERROR((ENTRI!Q16)," ") -> 01 | U16: =IFERROR((ENTRI!R16)," ") -> 07 | V16: =IFERROR((ENTRI!S16)," ") -> 2000 | W16: =T16&"-"&U16&"-"&V16 -> 01-07-2000 | X16: =IFERROR((ENTRI!T16)," ") -> 25 | Y16: =IFERROR((ENTRI!U16)," ") -> 25 | Z16: =IFERROR((ENTRI!V16)," ") -> 25 | AA16: =IFERROR((ENTRI!W16)," ") -> 25 | AB16: =IFERROR((ENTRI!X16)," ") -> S1 | AC16: =IFERROR((ENTRI!Y16)," ") -> PAI | AD16: =IFERROR((ENTRI!Z16)," ") -> 2004 | AE16: =IFERROR((ENTRI!AA16)," ") -> SUDAH | ... AQ16: =IFERROR((ENTRI!AM16)," ") -> 4444766668110012 | AR16: =E16&"."&H16&"."&AW16&"."&ENTRI!$E$4 -> 03.01.009.2025 | AS16: ="YPP.QH/KP.01."&E16&"/"&AW16&"/"&ENTRI!$E$4 -> YPP.QH/KP.01.03/009/2025 | AW16: 009
A17: =IF(B17=0," ",RANK(B17,$B$8:$B$178,1)) -> 39 | B17: =R17-Q17 -> 1998 | C17: 10 | D17: =IFERROR(IF(ENTRI!B17=$AZ$9,$BA$9,IF(ENTRI!B17=$AZ$10,$BA$10,IF(ENTRI!B17=$AZ$11,$BA$11,IF(ENTRI!B17=$AZ$12,$BA$12,IF(ENTRI!B17=$AZ$13,$BA$13,IF(ENTRI!B17=$AZ$14,$BA$14,IF(ENTRI!B17=$AZ$15,$BA$15,IF(ENTRI!B17=$AZ$16,$BA$16,IF(ENTRI!B17=$AZ$17,$BA$17,IF(ENTRI!B17=$AZ$18,$BA$18," "))))))))))," ") -> MI Qomarul Hidayah | E17: =IFERROR((ENTRI!C17)," ") -> 03 | F17: =A17 -> 39 | G17: =IFERROR((ENTRI!E17)," ") -> Guru | H17: =IFERROR((ENTRI!F17)," ") -> 01 | I17: =IFERROR((ENTRI!G17)," ") -> NAILI ROHMAH,S.E | J17: =IFERROR((ENTRI!H17)," ") -> 19800101 200507 03 01 11 | K17: =IFERROR((ENTRI!I17)," ") -> Trenggalek | L17: =IFERROR((ENTRI!J17)," ") -> 01 | M17: =IFERROR((ENTRI!K17)," ") -> 01 | N17: =IFERROR((ENTRI!L17)," ") -> 1980 | O17: =K17&","&" "&L17&"-"&M17&"-"&N17 -> Trenggalek, 01-01-1980 | P17: =IFERROR((ENTRI!N17)," ") -> 11 | Q17: =IFERROR((ENTRI!O17)," ") -> 07 | R17: =IFERROR((ENTRI!P17)," ") -> 2005 | S17: =P17&"-"&Q17&"-"&R17 -> 11-07-2005 | T17: =IFERROR((ENTRI!Q17)," ") -> 11 | U17: =IFERROR((ENTRI!R17)," ") -> 07 | V17: =IFERROR((ENTRI!S17)," ") -> 2005 | W17: =T17&"-"&U17&"-"&V17 -> 11-07-2005 | X17: =IFERROR((ENTRI!T17)," ") -> 20 | Y17: =IFERROR((ENTRI!U17)," ") -> 20 | Z17: =IFERROR((ENTRI!V17)," ") -> 20 | AA17: =IFERROR((ENTRI!W17)," ") -> 20 | AB17: =IFERROR((ENTRI!X17)," ") -> S1 | AC17: =IFERROR((ENTRI!Y17)," ") -> AKUNTASI | AD17: =IFERROR((ENTRI!Z17)," ") -> 2003 | AE17: =IFERROR((ENTRI!AA17)," ") -> SUDAH | ... AQ17: =IFERROR((ENTRI!AM17)," ") -> 20541857191001 | AR17: =E17&"."&H17&"."&AW17&"."&ENTRI!$E$4 -> 03.01.010.2025 | AS17: ="YPP.QH/KP.01."&E17&"/"&AW17&"/"&ENTRI!$E$4 -> YPP.QH/KP.01.03/010/2025 | AW17: 010
A18: =IF(B18=0," ",RANK(B18,$B$8:$B$178,1)) -> 27 | B18: =R18-Q18 -> 1996 | C18: 11 | D18: =IFERROR(IF(ENTRI!B18=$AZ$9,$BA$9,IF(ENTRI!B18=$AZ$10,$BA$10,IF(ENTRI!B18=$AZ$11,$BA$11,IF(ENTRI!B18=$AZ$12,$BA$12,IF(ENTRI!B18=$AZ$13,$BA$13,IF(ENTRI!B18=$AZ$14,$BA$14,IF(ENTRI!B18=$AZ$15,$BA$15,IF(ENTRI!B18=$AZ$16,$BA$16,IF(ENTRI!B18=$AZ$17,$BA$17,IF(ENTRI!B18=$AZ$18,$BA$18," "))))))))))," ") -> MI Qomarul Hidayah | E18: =IFERROR((ENTRI!C18)," ") -> 03 | F18: =A18 -> 27 | G18: =IFERROR((ENTRI!E18)," ") -> Guru | H18: =IFERROR((ENTRI!F18)," ") -> 01 | I18: =IFERROR((ENTRI!G18)," ") -> DUKAN KHOIRI,S.Pd.I | J18: =IFERROR((ENTRI!H18)," ") -> 19860526 200509 03 01 24 | K18: =IFERROR((ENTRI!I18)," ") -> Trenggalek | L18: =IFERROR((ENTRI!J18)," ") -> 26 | M18: =IFERROR((ENTRI!K18)," ") -> 05 | N18: =IFERROR((ENTRI!L18)," ") -> 1986 | O18: =K18&","&" "&L18&"-"&M18&"-"&N18 -> Trenggalek, 26-05-1986 | P18: =IFERROR((ENTRI!N18)," ") -> 01 | Q18: =IFERROR((ENTRI!O18)," ") -> 09 | R18: =IFERROR((ENTRI!P18)," ") -> 2005 | S18: =P18&"-"&Q18&"-"&R18 -> 01-09-2005 | T18: =IFERROR((ENTRI!Q18)," ") -> 01 | U18: =IFERROR((ENTRI!R18)," ") -> 09 | V18: =IFERROR((ENTRI!S18)," ") -> 2005 | W18: =T18&"-"&U18&"-"&V18 -> 01-09-2005 | X18: =IFERROR((ENTRI!T18)," ") -> 20 | Y18: =IFERROR((ENTRI!U18)," ") -> 20 | Z18: =IFERROR((ENTRI!V18)," ") -> 20 | AA18: =IFERROR((ENTRI!W18)," ") -> 20 | AB18: =IFERROR((ENTRI!X18)," ") -> S1 | AC18: =IFERROR((ENTRI!Y18)," ") -> PAI | AD18: =IFERROR((ENTRI!Z18)," ") -> 2010 | AE18: =IFERROR((ENTRI!AA18)," ") -> BELUM | ... AQ18: =IFERROR((ENTRI!AM18)," ") -> 20541857189001 | AR18: =E18&"."&H18&"."&AW18&"."&ENTRI!$E$4 -> 03.01.011.2025 | AS18: ="YPP.QH/KP.01."&E18&"/"&AW18&"/"&ENTRI!$E$4 -> YPP.QH/KP.01.03/011/2025 | AW18: 011
A19: =IF(B19=0," ",RANK(B19,$B$8:$B$178,1)) -> 60 | B19: =R19-Q19 -> 2001 | C19: 12 | D19: =IFERROR(IF(ENTRI!B19=$AZ$9,$BA$9,IF(ENTRI!B19=$AZ$10,$BA$10,IF(ENTRI!B19=$AZ$11,$BA$11,IF(ENTRI!B19=$AZ$12,$BA$12,IF(ENTRI!B19=$AZ$13,$BA$13,IF(ENTRI!B19=$AZ$14,$BA$14,IF(ENTRI!B19=$AZ$15,$BA$15,IF(ENTRI!B19=$AZ$16,$BA$16,IF(ENTRI!B19=$AZ$17,$BA$17,IF(ENTRI!B19=$AZ$18,$BA$18," "))))))))))," ") -> MTs Qomarul Hidayah | E19: =IFERROR((ENTRI!C19)," ") -> 04 | F19: =A19 -> 60 | G19: =IFERROR((ENTRI!E19)," ") -> Guru | H19: =IFERROR((ENTRI!F19)," ") -> 01 | I19: =IFERROR((ENTRI!G19)," ") -> RION ADI WIJAYA,S.Pd | J19: =IFERROR((ENTRI!H19)," ") -> 19880112 200807 04 01 01 | K19: =IFERROR((ENTRI!I19)," ") -> Trenggalek | L19: =IFERROR((ENTRI!J19)," ") -> 12 | M19: =IFERROR((ENTRI!K19)," ") -> 01 | N19: =IFERROR((ENTRI!L19)," ") -> 1988 | O19: =K19&","&" "&L19&"-"&M19&"-"&N19 -> Trenggalek, 12-01-1988 | P19: =IFERROR((ENTRI!N19)," ") -> 01 | Q19: =IFERROR((ENTRI!O19)," ") -> 07 | R19: =IFERROR((ENTRI!P19)," ") -> 2008 | S19: =P19&"-"&Q19&"-"&R19 -> 01-07-2008 | T19: =IFERROR((ENTRI!Q19)," ") -> 01 | U19: =IFERROR((ENTRI!R19)," ") -> 07 | V19: =IFERROR((ENTRI!S19)," ") -> 2020 | W19: =T19&"-"&U19&"-"&V19 -> 01-07-2020 | X19: =IFERROR((ENTRI!T19)," ") -> 5 | Y19: =IFERROR((ENTRI!U19)," ") -> 17 | Z19: =IFERROR((ENTRI!V19)," ") -> 17 | AA19: =IFERROR((ENTRI!W19)," ") -> 5 | AB19: =IFERROR((ENTRI!X19)," ") -> S1 | AC19: =IFERROR((ENTRI!Y19)," ") -> PBS/PBSI | AD19: =IFERROR((ENTRI!Z19)," ") -> 2013 | AE19: =IFERROR((ENTRI!AA19)," ") -> BELUM | ... AQ19: =IFERROR((ENTRI!AM19)," ") -> 20541857187001 | AR19: =E19&"."&H19&"."&AW19&"."&ENTRI!$E$4 -> 04.01.012.2025 | AS19: ="YPP.QH/KP.01."&E19&"/"&AW19&"/"&ENTRI!$E$4 -> YPP.QH/KP.01.04/012/2025 | AW19: 012
